Workbook
Name CA_Groupe: CONSOL_CR!$C$35
Name EBIT_Groupe: CONSOL_CR!$C$36
Name EBITDA_Groupe: CONSOL_CR!$C$38
Name Marge_EBIT_Groupe: CONSOL_CR!$C$37
Name Marge_EBITDA_Groupe: CONSOL_CR!$C$39
Name RN_Groupe: CONSOL_CR!$C$40
Name Taux_GBP_Cloture: PQ_TAUX_CHANGE!$F$6
Name Taux_SGD_Cloture: PQ_TAUX_CHANGE!$F$16
Name Taux_USD_Cloture: PQ_TAUX_CHANGE!$F$11

Sheet HOME
A1: 📑 SOMMAIRE COMPLET – TOUS LES ONGLETS (37 + 1 onglet)
B2: GROUPE MULTINATIONAL – CONSOLIDATION IFRS 18 | ESG / CSRD · Exercice 2025–2026
B5: Outil automatisé de consolidation · 5 entités · Société Mère FR + 4 Filiales Internationales
B7: LÉGENDE DES ONGLETS
B8: 🟢 VERT CLAIR | E8: 🔵 BLEU | H8: 🟠 ORANGE | K8: ⬛ ANTHRACITE
B9: Données sources (saisie / import) | E9: Calculs, consolidation & IFRS 18 | H9: Dashboards & reporting | K9: Navigation & documentation
B11: PLAN DU CLASSEUR – INDEX DES ONGLETS
B12: # | C12: Onglet | D12: Bloc | E12: Couleur | F12: Description | G12: Rôle
B13: 1 | C13: HOME | D13: Navigation | E13: Anthracite | F13: Page d'accueil et index de navigation | G13: Dashboard de lancement
B14: 2 | C14: GUIDE | D14: Navigation | E14: Anthracite | F14: Manuel utilisateur, légende, conventions IFRS 18 | G14: Documentation pédagogique
B15: 3 | C15: FR_ParentCo | D15: Sources 🟢 | E15: Vert | F15: Liasses comptables – Société Mère France (EUR) | G15: Saisie / import balances
B16: 4 | C16: DE_Filiale | D16: Sources 🟢 | E16: Vert | F16: Liasses comptables – Filiale Allemagne (EUR) | G16: Saisie / import balances
A17: N° | B17: Onglet | C17: Catégorie | D17: Description | E17: Statut | F17: Liasses comptables – Filiale Royaume-Uni (GBP) | G17: Saisie / import balances
A18: 1 | B18: HOME | C18: Navigation | D18: Accueil, légende, sommaire – point d'entrée du simulateur | E18: ✅ Complet | F18: Liasses comptables – Filiale États-Unis (USD) | G18: Saisie / import balances
A19: 2 | B19: GUIDE | C19: Documentation | D19: Guide utilisateur: couleurs, IFRS 18, ESG/CSRD, workflow | E19: ✅ Complet | F19: Liasses comptables – Filiale Singapour (SGD) | G19: Saisie / import balances
A20: 3 | B20: Méthodologie & Pédagogie | C20: Documentation | D20: §1-§10: IFRS 18, IAS 21, IFRS 3, Éliminations, PQ, Glossaire 60 termes, Audit Trail | E20: ✅ NOUVEAU | F20: Écritures d'élimination intercompagnies & capital | G20: Neutralisation flux internes
A21: 4 | B21: FR_ParentCo | C21: Données sources | D21: Bilan + CR Société Mère France (devise EUR) | E21: ✅ Complet | F21: Bilan consolidé agrégé + éliminations (IFRS) | G21: État financier consolidé
A22: 5 | B22: DE_Filiale | C22: Données sources | D22: Bilan + CR Filiale Allemagne (devise EUR) | E22: ✅ Complet | F22: Compte de résultat consolidé IFRS 18 (nouvelles catégories) | G22: P&L consolidé IFRS 18
A23: 6 | B23: UK_Filiale | C23: Données sources | D23: Bilan + CR Filiale Royaume-Uni (devise GBP) | E23: ✅ Complet | F23: Tableau des flux de trésorerie consolidé (méthode indirecte) | G23: Cash flow statement
A24: 7 | B24: US_Filiale | C24: Données sources | D24: Bilan + CR Filiale États-Unis (devise USD) | E24: ✅ Complet | F24: Mapping des postes IFRS 18 : Opérationnel / Investissement / Financement | G24: Reclassement IFRS 18
A25: 8 | B25: SG_Filiale | C25: Données sources | D25: Bilan + CR Filiale Singapour (devise SGD) | E25: ✅ Complet | F25: Notes annexes : Regroupements, GW, conversion, impôts différés | G25: Annexes IFRS
A26: 9 | B26: ELIM | C26: Consolidation | D26: Éliminations IC (7 écritures) + IFRS 3 Goodwill/NCI | E26: ✅ Complet | F26: Données ESG brutes : E (CO₂, énergie), S (emploi, parité), G (gouvernance) | G26: Collecte KPIs ESG
A27: 10 | B27: CONSOL_BILAN | C27: Consolidation | D27: Bilan consolidé groupe – toutes entités converties en EUR | E27: ✅ Complet | F27: Rapport CSRD structuré : E1-E5, S1-S4, G1-G2 (ESRS) | G27: Conformité CSRD/ESRS
A28: 11 | B28: CONSOL_CR | C28: Consolidation | D28: Compte de résultat consolidé – 5 catégories IFRS 18 | E28: ✅ Complet | F28: Dashboard financier interactif : KPIs, graphiques, comparaisons | G28: Analyse & décision
A29: 12 | B29: CONSOL_TRESORERIE | C29: Consolidation | D29: Tableau de flux de trésorerie consolidé (IAS 7) | E29: ✅ Complet | F29: Dashboard ESG interactif : scores, tendances, benchmarks | G29: Pilotage ESG
A30: 13 | B30: IFRS18_MAPPING | C30: IFRS 18 | D30: Mapping 5 catégories IFRS 18 pour tous les postes P&L | E30: ✅ Complet
A31: 14 | B31: NOTES_IFRS
A32: 15 | B32: ESG_DATA | C32: ESG/CSRD | D32: Données ESG brutes – KPIs E/S/G par entité et période | E32: ✅ Complet | F32: Méthode | G32: Taux de clôture | H32: Taux moyen | I32: Secteur
A33: 16 | B33: CSRD_RAPPORT | C33: ESG/CSRD | D33: Rapport de durabilité CSRD – ESRS E1/S1/G1 | E33: ✅ Complet | F33: Mère / Intégration Globale | G33: 1 | H33: 1 | I33: Holding / Services
A34: 17 | B34: DASHBOARD_FIN | C34: Dashboards | D34: Dashboard financier – KPIs, EBITDA, marges, levier | E34: ✅ Complet | F34: Intégration Globale | G34: 1 | H34: 1 | I34: Industrie manufacturière
A35: 18 | B35: DASHBOARD_ESG | C35: Dashboards | D35: Dashboard ESG – CO2, parité, accidents, gouvernance | E35: ✅ Complet | F35: Intégration Globale | G35: 1.165 | H35: 1.152 | I35: Technologies & Digital
A36: 19 | B36: DASHBOARD | C36: Dashboards | D36: Dashboard maître – synthèse Groupe toutes métriques | E36: ✅ Complet | F36: Intégration Globale | G36: 0.918 | H36: 0.925 | I36: Distribution & Retail
A37: 20 | B37: SRC_FR | C37: Sources PQ | D37: Source balances comptables FR – import Power Query | E37: ✅ Complet | F37: Intégration Globale | G37: 0.678 | H37: 0.682 | I37: Finance & Investissement
A38: 21 | B38: SRC_DE | C38: Sources PQ | D38: Source balances comptables DE – import Power Query | E38: ✅ Complet
A39: 22 | B39: SRC_UK | C39: Sources PQ | D39: Source balances comptables UK – import Power Query | E39: ✅ Complet
A40: 23 | B40: SRC_US
A41: 24 | B41: SRC_SG | C41: Sources PQ | D41: Source balances comptables SG – import Power Query | E41: ✅ Complet
A42: 25 | B42: PQ_MAPPING | C42: Power Query | D42: Mapping plans de comptes locaux → référentiel Groupe | E42: ✅ Complet
A43: 26 | B43: PQ_CODE
A44: 27 | B44: BALANCES_PQ
...

Sheet GUIDE_DÉMARRAGE
A1: 🚀 GUIDE DE DÉMARRAGE — Comment analyser les données d'une entreprise avec ce simulateur
A2: Niveau : Débutant · Durée : 10 min · Simulateur IFRS 18 · Groupe 5 entités (FR/DE/UK/US/SG) · Exercice 2025–2026
A4: 🗺️ QU'EST-CE QUE CE FICHIER ?
B5: 📁 STRUCTURE DU GROUPE | C5: 🎯 OBJECTIF DE L'OUTIL | D5: 👥 POUR QUI EST CET OUTIL ?
B6: • FR_ParentCo — France, EUR (maison mère) | C6: • Consolider 5 entités en 1 seul groupe | D6: • Étudiants en finance, audit, CG
B7: • DE_Filiale — Allemagne, EUR | C7: • Convertir les devises selon IAS 21 | D7: • Candidats en entretien finance
B8: • UK_Filiale — Royaume-Uni, GBP | C8: • Éliminer les transactions internes | D8: • Professionnels débutants en consolidation
B9: • US_Filiale — États-Unis, USD | C9: • Produire Bilan / CR / Trésorerie IFRS | D9: • Tout curieux de la norme IFRS 18
B10: • SG_Filiale — Singapour, SGD | C10: • Analyser KPIs financiers & ESG/CSRD
A13: 📂 CARTE DES ONGLETS — Qui fait quoi ?
A14: Couleur | B14: Rôle | C14: Onglets concernés | D14: Règle d'or
A15: 🟢 VERT | B15: SAISIE (tu écris ici) | C15: SRC_FR · SRC_DE · SRC_UK · SRC_US · SRC_SG · PQ_TAUX_CHANGE | D15: ✅ Seules ces cellules sont modifiables. C'est ton point d'entrée.
A16: 🔵 BLEU | B16: CALCULS AUTO (ne pas toucher) | C16: CONSOL_BILAN · CONSOL_CR · CONSOL_TRESORERIE · ELIM · BALANCES_PQ | D16: 🚫 Ces onglets se recalculent seuls. Ne jamais saisir manuellement.
A17: 🟠 ORANGE | B17: RÉSULTATS / DASHBOARDS | C17: DASHBOARD_FIN · DASHBOARD_ESG · DASHBOARD · CSRD_RAPPORT | D17: 👁️ Lecture seule. Tes KPIs, graphiques et rapports finaux.
A18: ⚫ NOIR | B18: NAVIGATION & AIDE | C18: HOME · GUIDE · GUIDE_DÉMARRAGE · Méthodologie & Pédagogie | D18: 📖 Pour comprendre, naviguer et consulter la documentation.
A19: 🔴 ROUGE | B19: CONFIG AVANCÉE (experts) | C19: PQ_MAPPING · PQ_CODE · PQ_ELIMINATIONS · PQ_DAX_MESURES | D19: ⚠️ Ne modifier que si tu maîtrises Power Query et M.
A21: 📋 PLAN EN 10 ÉTAPES — De zéro à l'analyse complète
A22: N° | B22: Titre de l'étape | C22: Ce que tu fais concrètement (mode opératoire) | D22: Onglet(s) à ouvrir | E22: Durée
A23: 1 | B23: 🔑 PRÉREQUIS | C23: À l'ouverture : › Barre jaune « Macros désactivées » → cliquer « Activer le contenu » › Mode protégé → cliquer « Modifier quand même » › Enregistrer en .xlsm : Fichier → Enregistrer sous → Classeur Excel avec macros | D23: Tous les onglets | E23: 2 min
A24: 2 | B24: 🗺️ EXPLORATION | C24: Parcourir SANS rien modifier : ① HOME → comprendre la légende des couleurs d'onglets ② GUIDE → lire les conventions de saisie ③ GUIDE_DÉMARRAGE (ici) → mémoriser le plan en 10 étapes Règle d'or : les cellules bleues contiennent des formules → ne jamais saisir dessus. | D24: HOME · GUIDE GUIDE_DÉMARRAGE | E24: 5 min
A25: 3 | B25: 💱 TAUX DE CHANGE | C25: Onglet PQ_TAUX_CHANGE › Section 1 (lignes 5 à 20) Saisir dans la colonne F les taux BCE à la date de clôture : › F6 = GBP/EUR clôture (ex : 1.165) › F9 = GBP/EUR moyen annuel (ex : 1.155) › F11 = USD/EUR clôture (ex : 0.918) › F14 = USD/EUR moyen annuel (ex : 0.925) › F16 = SGD/EUR clôture (ex : 0.678) › F19 = SGD/EUR moyen annuel (ex : 0.682) Source officielle : ecb.europa.eu › Statistics › Exchange Rates | D25: PQ_TAUX_CHANGE › Colonne F | E25: 5 min
A26: 4 | B26: 📥 DONNÉES FR (Société mère) | C26: Onglet SRC_FR → coller les balances comptables annuelles de la maison mère : › Col A = Code compte (ex : 701000) › Col B = Libellé du compte › Colonnes suivantes = Montants par mois ou trimestre Comment importer : export depuis SAP / SAGE / Cegid → Ctrl+C → Ctrl+V Le plan de comptes doit correspondre à celui de PQ_MAPPING (colonne CodeCompteLocal). ✅ Vérification : onglet FR_ParentCo › cellule D30 (TOTAL ACTIF) doit être positif. | D26: SRC_FR → FR_ParentCo | E26: 15–30 min
A27: 5 | B27: 📥 DONNÉES FILIALES (4 entités étrangères) | C27: Même opération × 4. ⚠️ Saisir TOUJOURS en monnaie LOCALE (conversion automatique). › SRC_DE → DE_Filiale (EUR, aucune conversion nécessaire) › SRC_UK → UK_Filiale (GBP → EUR converti via taux §3) › SRC_US → US_Filiale (USD → EUR converti automatiquement) › SRC_SG → SG_Filiale (SGD → EUR converti automatiquement) Vérification : chaque onglet filiale › cellule D26 (TOTAL ACTIF) > 0 | D27: SRC_DE · SRC_UK SRC_US · SRC_SG | E27: 15–30 min par entité
A28: 6 | B28: ✂️ ÉLIMINATIONS IC (Transactions internes) | C28: Onglet ELIM › Section 1 (lignes 5 à 12) Saisir TOUTES les opérations réalisées ENTRE entités du groupe : › Ventes interco › Management fees › Prêts inter-compagnies › Dividendes internes Pour chaque ligne : montant en monnaie locale + sélectionner la devise. Le montant en EUR est calculé automatiquement. 📖 Règle IFRS fondamentale : tout flux interne = double comptage = doit être éliminé. | D28: ELIM › §1 et §2 | E28: 10–20 min
A29: 7 | B29: ⚡ RAFRAÎCHIR (Bouton unique) | C29: Aller sur HOME › cliquer « 🔄 TOUT RAFRAÎCHIR » › attendre. Le programme exécute 4 actions automatiquement : ① Recharge tous les Power Query (normalisation et conversion des données) ② Recalcule toutes les formules IFRS (IAS 21, IFRS 3, éliminations IC) ③ Met à jour les 3 dashboards (financier, ESG, maître) ④ Inscrit une ligne dans AUDIT_LOG (traçabilité avec horodatage) Message de confirmation en fin : « ✅ Rafraîchissement terminé – X connexions » | D29: HOME › Bouton orange | E29: 1–2 min
A30: 8 | B30: ✅ VÉRIFICATIONS (Contrôle qualité) | C30: Vérifier ces 4 indicateurs avant d'analyser : ① CONSOL_BILAN › ligne 43 → doit afficher « ✅ BILAN ÉQUILIBRÉ » Si ❌ : revoir les éliminations IC (onglet ELIM §1 et §2) ② CONSOL_CR → aucun #VALEUR! ou #REF! dans le tableau des données Si erreur : vérifier que les onglets SRC_* contiennent bien des données ③ CONSOL_TRESORERIE › ligne 29 → doit afficher « ✅ OK » Si ❌ : vérifier la trésorerie d'ouverture (cellule C27) ④ Alt+F8 → sélectionner ValiderFiliales() → Exécuter → lire le rapport RAG | D30: CONSOL_BILAN CONSOL_CR CONSOL_TRESORERIE | E30: 5 min
A31: 9 | B31: 📊 ANALYSER (L'objectif final) | C31: Consulter dans cet ordre pour une analyse complète : ① DASHBOARD_FIN → Vue globale : CA, EBIT, EBITDA, RN, Dette Nette, Levier ② CONSOL_CR → P&L détaillé par entité + variations Δ% vs N-1 + TEI ③ CONSOL_BILAN → Structure : Goodwill, Capitaux propres, Dettes, Actifs ④ CONSOL_TRESORERIE → Cash opérationnel vs CAPEX vs Financement (FCF) ⑤ DASHBOARD_ESG → CO₂ Scope 1-2-3, parité H/F, accidents, gouvernance → Les KPIs sont expliqués en détail dans la Section D ci-dessous | D31: DASHBOARD_FIN CONSOL_CR CONSOL_BILAN CONSOL_TRESORERIE DASHBOARD_ESG | E31: 30–60 min
A32: 10 | B32: 📤 EXPORTER (Partager les résultats) | C32: Option A – PDF en 1 clic (recommandé) : Alt+F8 → ExporterPDF() → OK → Génère « IFRS18_Rapport_2025-XX-XX.pdf » Contenu : HOME + Bilan + CR + Trésorerie + IFRS18_MAPPING + Dashboards + CSRD Option B – PDF manuel sélectif : Ctrl+clic sur les onglets à exporter → Fichier → Exporter → Créer PDF/XPS Option C – Partage du fichier Excel : Fichier → Enregistrer sous → Format .xlsm Nom suggéré : IFRS18_Consolidation_[NomEntreprise]_[Exercice].xlsm | D32: HOME › Bouton PDF ou Alt+F8 | E32: 2–5 min
A34: 📈 SECTION D — COMMENT LIRE LES 10 KPIs FINANCIERS CLÉS
A35: KPI | B35: Définition & Formule | C35: Où le trouver dans le fichier | D35: Benchmark sectoriel | E35: Comment l'interpréter
A36: CA Groupe (k€) | B36: Chiffre d'affaires consolidé = Σ CA 5 entités − Éliminations IC (IFRS 18 Catégorie ①) | C36: CONSOL_CR › K7 DASHBOARD_FIN › B6 Valeur : 817 075 k€ | D36: Croissance vs N-1 : > +5% = dynamisme 0 à +5% = stabilité < 0% = vigilance | E36: Δ% vs N-1 = −0.4% → CA quasi stable. Vérifier si baisse de volumes (prix stable) ou baisse de prix (volumes stables).
A37: Marge EBIT (%) | B37: EBIT / CA EBIT = Résultat Opérationnel = uniquement Catégorie ① IFRS 18 (SANS investissement ni financement) | C37: CONSOL_CR › K14 / K7 DASHBOARD_FIN › G6 Valeur : 18.8% | D37: Industrie lourde : 8–12% Services / Conseil : 15–25% Tech / SaaS : 20–30% Distribution : 3–6% | E37: 18.8% = solide pour industrie. SG_Filiale est la plus rentable (25%). Chercher pourquoi : mix produits, coûts ?
A38: EBITDA (k€) | B38: EBIT + Dotations aux amortissements = Proxy du cash opérationnel généré (avant IS, intérêts, amortissements) | C38: CONSOL_CR › C38 DASHBOARD_FIN › B11 Valeur : 216 451 k€ | D38: Comparer à CAPEX : CAPEX / EBITDA < 30% = OK CAPEX / EBITDA > 60% = capital intensif | E38: CAPEX = 48 200 k€ CAPEX/EBITDA = 22% → investissement maîtrisé. EBITDA positif = génération de cash réelle.
A39: Marge EBITDA (%) | B39: EBITDA / CA = Rentabilité avant effets comptables (amortissements, IS, intérêts) | C39: CONSOL_CR › C38 / K7 DASHBOARD_FIN › G11 Valeur : 26.5% | D39: Industrie : 15–20% Tech : 25–35% Santé : 20–30% | E39: 26.5% confirme des marges robustes. Supérieur à Marge EBIT (18.8%) de 7.7 pts = impact normal des amortissements.
A40: TEI (Taux Effectif IS) | B40: IS total / Résultat avant IS = Taux d'imposition réellement supporté (≠ taux légal nominal) | C40: CONSOL_CR › C43 Valeur : 27.8% | D40: Taux légaux : FR 25%, UK 25% US 21%, DE 30%, SG 17% TEI groupe ≈ moyenne pondérée | E40: 27.8% cohérent avec le mix pays. TEI < 15% : structures d'optimisation ? TEI > 40% : provisions IS exceptionnelles ?
A41: Levier DN/EBITDA | B41: Dette Nette / EBITDA Dette Nette = Dettes fin. − Trésorerie = Nb d'années d'EBITDA pour rembourser | C41: CONSOL_CR › C44 DASHBOARD_FIN › F13 Valeur : 0.95x | D41: < 1x = quasi pas endetté 1–2x = faible dette 2–4x = endettement modéré > 5x = risque élevé | E41: 0.95x = groupe très peu endetté. Capacité à lever de la dette si besoin. M&A ou CAPEX expansif sont possibles.
A42: Dette Nette (k€) | B42: Dettes financières (LT+CT) − Trésorerie Positif = groupe endetté Négatif = trésorerie excédentaire | C42: DASHBOARD_FIN › K11 Valeur : 205 512 k€ | D42: Comparer aux CP : Gearing (DN/CP) < 50% = conservateur Gearing > 100% = agressif | E42: 205 512 k€ vs EBITDA 216 451 k€ → couverture quasi 1:1 = situation saine. Surveiller les échéances de remboursement.
A43: Résultat Net (k€) | B43: Profit après IS, NCI et activ. abandonnées = Ce qui revient aux actionnaires du groupe (hors intérêts minoritaires NCI) | C43: CONSOL_CR › K30 Valeur : 82 110 k€ | D43: Marge nette saine : > 8–10% Marge nette ici : 10.0% | E43: Δ vs N-1 = −35% → forte baisse. À investiguer : IS exceptionnel ? Ou dégradation opérationnelle réelle ?
A44: Flux exploitation (IAS 7, k€) | B44: Cash généré par l'activité courante (méthode indirecte : RN + amort. ± BFR) Après IS payés, avant CAPEX | C44: CONSOL_TRESORERIE › C12 Valeur : 133 648 k€ | D44: FCF = Flux exploit. − CAPEX FCF > 0 = autofinancement FCF < 0 = dépendance financement extérieur | E44: FCF = 133 648 − 48 200 − 9 200 = 76 248 k€ Le groupe génère du cash libre positif. Peut financer sa croissance en interne.
A45: Écart de conversion (OCI, IAS 21) | B45: Gain / Perte de change sur conversion des filiales étrangères en EUR → OCI : n'impacte PAS le P&L ! | C45: CONSOL_BILAN › J25 N'affecte pas CONSOL_CR (traitement OCI IFRS) | D45: Surveiller si devises volatiles (GBP, USD, SGD) Significatif si > 5% des CP | E45: En OCI = impact uniquement sur les Capitaux Propres du bilan. Couvrir si exposition > 10 M€.
...

Sheet GUIDE
B2: 📘 GUIDE UTILISATEUR – CONVENTIONS & PÉDAGOGIE IFRS 18
B5: 1. LÉGENDE DES COULEURS & CONVENTIONS DE SAISIE
B6: Couleur fond | C6: Usage | D6: Règle de saisie | E6: Exemple
B7: 🟩 Vert clair (#D5E8D4) | C7: Cellules source saisie | D7: Données manuelles ou importées | E7: Chiffre d'affaires entité FR
B8: 🔵 Bleu clair (#DAE8FC) | C8: Cellules de calcul | D8: NE PAS MODIFIER – formules auto | E8: Total consolidé agrégé
B9: 🟠 Orange (#FFE6CC) | C9: Dashboards KPIs | D9: Lecture seule – graphiques dyn. | E9: Marge EBITDA groupe
B10: 🟨 Jaune (#FFFF88) | C10: Hypothèses clés | D10: Paramètres sensibles – documenter | E10: Taux de change GBP/EUR
B12: 2. IFRS 18 – NOUVEAUTÉS (Application 2027, préparation 2025-2026)
B13: Nouveauté IFRS 18 | C13: Ancien (IAS 1) | D13: Nouveau traitement | E13: Impact consolidation
B14: 5 catégories P&L obligatoires | C14: Présentation libre | D14: Opérationnel / Invest. / Financement / Impôts / Discontinu | E14: Reclassement total requis
B15: Sous-totaux imposés | C15: Facultatifs | D15: Profit avant financement & impôt obligatoire | E15: Nouveau KPI groupe clé
B16: Management Performance Measures | C16: Non encadrées | D16: Divulgation & réconciliation obligatoires | E16: Notes annexes renforcées
B17: Résultat opérationnel isolé | C17: Résultat courant libre | D17: Charges/produits non opérationnels exclus | E17: Séparation stricte analytique
B18: Investissement (Investing) | C18: Intégré résultat global | D18: Produits d'actifs non opérationnels isolés | E18: Isolation des flux invest.
B20: 3. ESG / CSRD – CADRE RÉGLEMENTAIRE & ESRS
B21: Pilier CSRD/ESRS | C21: Standards applicables | D21: Indicateurs couverts dans ce fichier
B22: E – Environnement | C22: ESRS E1 (Climat), E2 (Pollution), E4 (Biodiv.) | D22: CO₂ scope 1-2-3, énergie renouvelable, déchets
B23: S – Social | C23: ESRS S1 (Employés), S2 (Chaîne val.) | D23: Effectifs, parité H/F, accidents, formation
B24: G – Gouvernance | C24: ESRS G1 (Éthique, conduite affaires) | D24: Diversité CA, politique anti-corruption, alertes
B25: CSRD Scope | C25: Entreprises > 500 salariés ou cotées | D25: Rapport de durabilité obligatoire dès 2025
B27: 4. WORKFLOW DE CONSOLIDATION – ORDRE DE SAISIE RECOMMANDÉ
B28: Étape | C28: Onglet(s) | D28: Action
B29: ① Paramétrer les taux de change | C29: FR_ParentCo (zone paramètres) | D29: Saisir les taux de clôture et moyens par devise
B30: ② Saisir les liasses locales | C30: FR / DE / UK / US / SG | D30: Importer ou saisir balances par entité
B31: ③ Contrôler les flux intercos | C31: ELIM | D31: Vérifier et valider les éliminations automatiques
B32: ④ Vérifier la consolidation | C32: CONSOL_BILAN / CONSOL_CR | D32: Contrôler la balance des états financiers
B33: ⑤ Compléter le mapping IFRS 18 | C33: IFRS18_MAPPING | D33: Reclasser les postes selon les 5 catégories
B34: ⑥ Saisir les données ESG | C34: ESG_DATA | D34: Renseigner les KPIs environnementaux, sociaux, gouvernance
B35: ⑦ Analyser les dashboards | C35: DASHBOARD_FIN / DASHBOARD_ESG | D35: Lire les indicateurs et partager le rapport

Sheet Méthodologie & Pédagogie
A1: 📚 MÉTHODOLOGIE & PÉDAGOGIE – GUIDE COMPLET DU SIMULATEUR IFRS 18 / CONSOLIDATION / ESG
A2: Simulateur de Consolidation · Groupe Multinational · 5 Entités · IFRS 18 | IAS 21 | IFRS 3 | ESG/CSRD · Exercice 2025–2026
A4: 📋 TABLE DES MATIÈRES
A5: Réf. | B5: Section | C5: Ligne de départ | D5: Description rapide
A6: §1 | B6: IFRS 18 – Présentation des États Financiers | C6: ~Ligne 15 | D6: Nouveau standard 2027 – 5 catégories P&L obligatoires
A7: §2 | B7: IAS 21 – Effets des variations des taux de change | C7: ~Ligne 50 | D7: Conversion des filiales étrangères en EUR
A8: §3 | B8: IFRS 3 – Regroupements d'entreprises | C8: ~Ligne 80 | D8: Goodwill, PPA, Intérêts minoritaires
A9: §4 | B9: Éliminations intercompagnies | C9: ~Ligne 110 | D9: IC transactions, dividendes, prêts intragroupe
A10: §5 | B10: Méthode de consolidation – Workflow complet | C10: ~Ligne 140 | D10: Ordre et logique du processus de consolidation
A11: §6 | B11: Power Query – Architecture & logique M | C11: ~Ligne 165 | D11: Automatisation et modélisation des flux de données
A12: §7 | B12: ESG / CSRD – Cadre réglementaire ESRS | C12: ~Ligne 190 | D12: ESRS E1/S1/G1 – Scope 1-2-3 CO2
A13: §8 | B13: Glossaire CCA | C13: ~Ligne 215 | D13: 60+ termes de consolidation définis
A14: §9 | B14: Schémas & Flux (texte structuré) | C14: ~Ligne 270 | D14: Workflow visuel de consolidation
A15: §10 | B15: Audit Trail – Traçabilité des calculs | C15: ~Ligne 315 | D15: Références croisées et contrôles qualité
A17: §1 IFRS 18 – PRÉSENTATION DES ÉTATS FINANCIERS (en vigueur 2027, préparation 2025-2026)
A18: IFRS 18 remplace IAS 1 – Il impose une structure OBLIGATOIRE du P&L en 5 catégories, interdit les catégories propriétaires, et exige la réconciliation des Management Performance Measures (MPM) en annexe. Application obligatoire 1er janv. 2027 (comparatif 2026).
A20: Catégorie IFRS 18 | B20: § Référence | C20: Contenu obligatoire | D20: Exemples dans le Groupe | E20: vs IAS 1 ancien
A21: ① EXPLOITATION | B21: §45-55 | C21: Revenus IFRS 15, coûts directs, charges d'exploitation, DAP actifs opérationnels | D21: CA, Achats, Salaires, DAP PP&E — 5 entités du groupe | E21: Résultat courant (non défini normativement)
A22: ② INVESTISSEMENT | B22: §56-68 | C22: Produits/charges d'actifs NON utilisés dans l'exploitation principale. Rendements financiers. | D22: Dividendes IC reçus, plus-values cessions, produits placements CT | E22: Résultat financier (mélangé avec financement)
A23: ③ FINANCEMENT | B23: §69-72 | C23: Coûts de financement des passifs financiers : intérêts emprunts bancaires + intérêts dettes locatives IFRS 16 | D23: Charges intérêts LT, intérêts baux IFRS 16 — toutes entités | E23: Résultat financier (non séparé de investing)
A24: ④ IMPÔTS | B24: §73-80 | C24: IS courant (IAS 12) + impôts différés. TOUJOURS présenté séparément. Ne peut pas être noyé dans une autre catégorie. | D24: Charge IS courant + variation DTA/DTL par entité | E24: Ligne IS dans résultat courant (similaire)
A25: ⑤ DISCONTINU | B25: §81-85 | C25: Résultat net post-IS des activités abandonnées IFRS 5. UNE SEULE ligne nette dans le P&L. | D25: Non applicable ex. 2025 – prévu pour extensions futures | E25: Résultat net séparé (similaire mais non codifié)
A27: 📌 MANAGEMENT PERFORMANCE MEASURES (MPM) – Nouveauté clé IFRS 18
A28: Définition MPM : | B28: Tout sous-total de résultat communiqué EXTERNEMENT par la direction et NON requis par IFRS 18 (ex: EBITDA ajusté, résultat opérationnel courant, résultat récurrent, résultat sous-jacent)
A29: Obligation : | B29: Divulgation OBLIGATOIRE en annexe avec réconciliation ligne-à-ligne vers le sous-total IFRS 18 le plus proche (§B1-B12). Interdit de mettre les MPM en face avant du P&L.
A30: Impact Groupe : | B30: L'EBITDA Groupe des dashboards DOIT être réconcilié vers Résultat opérationnel §47. Onglet NOTES_IFRS lignes 15-22.
A31: Onglets liés : | B31: IFRS18_MAPPING colonnes F:J → NOTES_IFRS B15:B22 → CONSOL_CR lignes sous-totaux
A32: Référence : | B32: IFRS 18 §B1-B12 (Guide d'application) + IASB Exposure Draft avril 2019 → Standard final avril 2024
A33: 📊 SCHÉMA P&L IFRS 18 – SOUS-TOTAUX OBLIGATOIRES (§47-48)
A34: Catégories ① | B34: Produits d'exploitation (IFRS 15 + autres) | C34: xxx €
B35: – Charges d'exploitation, salaires, DAP | C35: (xxx €)
A36: SOUS-TOTAL ① | B36: ═══ RÉSULTAT D'EXPLOITATION ═══ | C36: xxx € | D36: ⬅ OBLIGATOIRE §47
A37: Catégories ② | B37: + Produits d'investissement (dividendes, plus-values) | C37: +xxx €
A38: SOUS-TOTAL ①+② | B38: ═══ RÉSULTAT AVANT FINANCEMENT & IMPÔTS ═══ | C38: xxx € | D38: ⬅ NOUVEAU §48
A39: Catégories ③ | B39: – Charges de financement (intérêts, IFRS 16) | C39: (xxx €)
A40: SOUS-TOTAL ①+②+③ | B40: ═══ RÉSULTAT AVANT IMPÔTS ═══ | C40: xxx € | D40: ⬅ Classique
A41: Catégories ④ | B41: – Charge d'impôt (IS courant + différé) | C41: (xxx €)
B42: ═══ RÉSULTAT DES ACTIVITÉS POURSUIVIES ═══ | C42: xxx €
A43: Catégories ⑤ | B43: + Résultat activités abandonnées (net IS) | C43: ±xxx €
A44: RÉSULTAT NET | B44: ═══ RÉSULTAT NET CONSOLIDÉ ═══ | C44: xxx € | D44: ⬅ BOTTOM LINE
...

Sheet FR_ParentCo
B2: 🇫🇷 FR_ParentCo – SOCIÉTÉ MÈRE FRANCE · Liasse Comptable Locale · Exercice 2025-2026
B4: ⚙️ PARAMÈTRES ENTITÉ
B5: Entité : | C5: FR_ParentCo – Holding Groupe
B6: Pays / Devise : | C6: France · EUR (€)
B7: % Détention : | C7: 100% – Société Mère
B8: Méthode : | C8: Intégration Globale
B9: Taux de clôture : | C9: 1.0000 (EUR/EUR)
B10: Taux moyen : | C10: 1.0000 (EUR/EUR)
B11: Exercice : | C11: 01/01/2025 – 31/12/2025
B13: BILAN CONSOLIDÉ LOCAL – ACTIF (en k€) | I13: BILAN – PASSIF (en k€)
B14: Poste IFRS | C14: Compte | D14: N (2025) k€ | E14: N-1 (2024) k€ | F14: Δ k€ | G14: Note | I14: Poste IFRS | J14: Compte | K14: N (2025) k€ | L14: N-1 (2024) k€ | M14: Δ k€ | N14: Note
B15: ACTIFS NON COURANTS | I15: CAPITAUX PROPRES
B16: Immobilisations incorporelles (GW inclus) | C16: 21xx | D16: 85000 | E16: 82000 | F16: =D16-E16 -> 3000 | G16: Note 3 – GW | I16: Capital social | J16: 101x | K16: 50000 | L16: 50000
B17: Immobilisations corporelles (PP&E) | C17: 22xx | D17: 142000 | E17: 138500 | F17: =D17-E17 -> 3500 | G17: IFRS 16 | I17: Primes d'émission & réserves | J17: 104x-106x | K17: 128500 | L17: 115200
B18: Actifs droits d'utilisation (IFRS 16) | C18: 232x | D18: 28500 | E18: 31200 | F18: =D18-E18 -> -2700 | G18: Baux | I18: Résultat de l'exercice | J18: 120x | K18: 32800 | L18: 28400 | N18: Lié au CR
B19: Participations & titres mis en équivalence | C19: 261x | D19: 95000 | E19: 90000 | F19: =D19-E19 -> 5000 | G19: Méthode MEE | I19: Autres réserves / OCI (IFRS 9 & IAS 19) | J19: 10xx | K19: -4200 | L19: -3100 | N19: IAS 19
B20: Impôts différés actifs | C20: 274x | D20: 12400 | E20: 11800 | F20: =D20-E20 -> 600 | G20: IAS 12 | I20: Intérêts minoritaires (NCI) | J20: 1044 | K20: 18700 | L20: 16900 | N20: IFRS 10
B21: Autres actifs non courants | C21: 27xx | D21: 8500 | E21: 7200 | F21: =D21-E21 -> 1300 | I21: TOTAL CAPITAUX PROPRES | K21: =SUM(K16:K20) -> 225800 | L21: =SUM(L16:L20) -> 207400 | M21: =K21-L21 -> 18400
B22: TOTAL ACTIFS NON COURANTS | D22: =SUM(D16:D21) -> 371400 | E22: =SUM(E16:E21) -> 360700 | F22: =D22-E22 -> 10700 | I22: PASSIFS NON COURANTS
B23: ACTIFS COURANTS | I23: Emprunts & dettes financières LT | J23: 164x | K23: 125000 | L23: 132000 | N23: IFRS 9
B24: Stocks & en-cours | C24: 31xx-35xx | D24: 45200 | E24: 43800 | F24: =D24-E24 -> 1400 | G24: IAS 2 | I24: Dettes locatives LT (IFRS 16) | J24: 1674 | K24: 22800 | L24: 25600 | N24: IFRS 16
B25: Créances clients & comptes rattachés | C25: 411x | D25: 67800 | E25: 71200 | F25: =D25-E25 -> -3400 | G25: IFRS 9 | I25: Provisions pour risques LT | J25: 151x | K25: 15400 | L25: 14200 | N25: IAS 37
B26: Créances intercompagnies | C26: 451x | D26: 23500 | E26: 19800 | F26: =D26-E26 -> 3700 | G26: ⚠️ ELIM | I26: Impôts différés passifs | J26: 155x | K26: 18900 | L26: 17500 | N26: IAS 12
B27: Autres créances & charges constatées d'avance | C27: 408x-486x | D27: 8900 | E27: 7600 | F27: =D27-E27 -> 1300 | I27: TOTAL PASSIFS NON COURANTS | K27: =SUM(K23:K26) -> 182100 | L27: =SUM(L23:L26) -> 189300 | M27: =K27-L27 -> -7200
B28: Trésorerie & équivalents | C28: 512x-530x | D28: 54300 | E28: 48700 | F28: =D28-E28 -> 5600 | G28: IAS 7 | I28: PASSIFS COURANTS
B29: TOTAL ACTIFS COURANTS | D29: =SUM(D24:D28) -> 199700 | E29: =SUM(E24:E28) -> 191100 | F29: =D29-E29 -> 8600 | I29: Dettes fournisseurs & comptes rattachés | J29: 401x | K29: 38200 | L29: 35600
B30: TOTAL ACTIF | D30: =D22+D29 -> 571100 | E30: =E22+E29 -> 551800 | F30: =D30-E30 -> 19300 | G30: ✔ Équilibre | I30: Dettes financières CT & lignes de crédit | J30: 519x | K30: 28500 | L30: 22300
I31: Dettes intercompagnies | J31: 451x | K31: 21400 | L31: 18200 | N31: ⚠️ ELIM
I32: Autres dettes & produits constatés d'avance | J32: 487x | K32: 12800 | L32: 11400
I33: TOTAL PASSIFS COURANTS | K33: =SUM(K29:K32) -> 100900 | L33: =SUM(L29:L32) -> 87500 | M33: =K33-L33 -> 13400
I34: TOTAL PASSIF | K34: =K21+K27+K33 -> 508800 | L34: =L21+L27+L33 -> 484200 | M34: =K34-L34 -> 24600 | N34: ✔ Équilibre
B36: COMPTE DE RÉSULTAT LOCAL – IFRS 18 (5 catégories) (en k€)
B37: Poste IFRS 18 | C37: Catégorie | D37: N (2025) k€ | E37: N-1 (2024) k€ | F37: Δ % | G37: Note IFRS
B38: ① EXPLOITATION (OPERATING)
B39: Chiffre d'affaires net | C39: Opérationnel | D39: 285000 | E39: 268000 | F39: =IFERROR((D39-E39)/ABS(E39),"") -> 0.063432836 | G39: IFRS 15
B40: Variation de stocks de produits finis | C40: Opérationnel | D40: 1800 | E40: -2100 | F40: =IFERROR((D40-E40)/ABS(E40),"") -> 1.8571429 | G40: IAS 2
B41: Autres produits opérationnels | C41: Opérationnel | D41: 3200 | E41: 2800 | F41: =IFERROR((D41-E41)/ABS(E41),"") -> 0.14285714
B42: Achats consommés & charges externes | C42: Opérationnel | D42: -142000 | E42: -135000 | F42: =IFERROR((D42-E42)/ABS(E42),"") -> -0.051851852
B43: Charges de personnel | C43: Opérationnel | D43: -68000 | E43: -64500 | F43: =IFERROR((D43-E43)/ABS(E43),"") -> -0.054263566 | G43: IAS 19
B44: Amortissements (PP&E + DU IFRS 16) | C44: Opérationnel | D44: -22000 | E44: -21200 | F44: =IFERROR((D44-E44)/ABS(E44),"") -> -0.037735849 | G44: IAS 16/36
...

Sheet DE_Filiale
B2: 🇩🇪 DE_Filiale – FILIALE ALLEMAGNE · Exercice 2025-2026
B4: ⚙️ PARAMÈTRES ENTITÉ
B5: Entité : | C5: DE_Filiale
B6: Pays / Devise : | C6: Allemagne · EUR (€)
B7: % Détention : | C7: 1
B8: Méthode : | C8: Intégration Globale
B9: Taux de clôture : | C9: 1.0000 (EUR/EUR)
B10: Taux moyen : | C10: 1.0000 (EUR/EUR)
B11: Secteur : | C11: Industrie manufacturière
B13: BILAN LOCAL (en k€) | I13: 🔄 CONVERSION EN EUR (pour consolidation)
B14: Poste IFRS | C14: Compte | D14: N (2025) | E14: N-1 (2024) | F14: Δ | G14: Note | I14: Poste | J14: Taux utilisé | K14: Local | L14: Converti EUR | M14: Méthode
B15: ACTIFS NON COURANTS | I15: Actifs/Passifs | J15: Taux clôture | K15: 1 | L15: 1 | M15: IAS 21 §23
B16: Immobilisations incorporelles | C16: 21xx | D16: 18000 | E16: 17500 | F16: =D16-E16 -> 500 | I16: P&L / Charges | J16: Taux moyen | K16: 1 | L16: 1 | M16: IAS 21 §39
B17: Immobilisations corporelles (PP&E) | C17: 22xx | D17: 95000 | E17: 91000 | F17: =D17-E17 -> 4000 | I17: Capitaux propres | J17: Taux historique | K17: 1 | L17: 1 | M17: IAS 21 §39
B18: Impôts différés actifs & autres | C18: 274x | D18: 5200 | E18: 4800 | F18: =D18-E18 -> 400 | I18: Écart de conversion | J18: Différence | M18: OCI (IAS 21)
B19: TOTAL ACTIFS NON COURANTS | D19: =SUM(D16:D18) -> 118200 | E19: =SUM(E16:E18) -> 113300 | F19: =D19-E19 -> 4900
B20: ACTIFS COURANTS
B21: Stocks | C21: 31xx | D21: 62000 | E21: 58000 | F21: =D21-E21 -> 4000
B22: Créances clients | C22: 411x | D22: 38000 | E22: 35000 | F22: =D22-E22 -> 3000
B23: Créances interco | C23: 451x | D23: 12500 | E23: 10800 | F23: =D23-E23 -> 1700 | G23: ⚠️ ELIM
B24: Trésorerie | C24: 512x | D24: 24000 | E24: 21000 | F24: =D24-E24 -> 3000
B25: TOTAL ACTIFS COURANTS | D25: =SUM(D21:D24) -> 136500 | E25: =SUM(E21:E24) -> 124800 | F25: =D25-E25 -> 11700
B26: TOTAL ACTIF | D26: =D19+D25 -> 254700 | E26: =E19+E25 -> 238100 | F26: =D26-E26 -> 16600 | G26: ✔
B28: COMPTE DE RÉSULTAT LOCAL – IFRS 18 (k monnaie locale)
B29: Poste | C29: Cat. IFRS 18 | D29: N (2025) | E29: N-1 (2024) | F29: Δ % | G29: Note
B30: Chiffre d'affaires | C30: Opérationnel | D30: 168000 | E30: 155000 | F30: =IFERROR((D30-E30)/ABS(E30),"") -> 0.083870968 | G30: IFRS 15
B31: Achats & charges opérat. | C31: Opérationnel | D31: -138500 | E31: -130200 | F31: =IFERROR((D31-E31)/ABS(E31),"") -> -0.06374808
B32: Charges de personnel | C32: Opérationnel | D32: -36960 | E32: -34100 | F32: =IFERROR((D32-E32)/ABS(E32),"") -> -0.083870968
B33: Amortissements | C33: Opérationnel | D33: -8400 | E33: -7750 | F33: =IFERROR((D33-E33)/ABS(E33),"") -> -0.083870968
B34: RÉSULTAT OPÉRATIONNEL (EBIT) | C34: Opérationnel | D34: =SUM(D30:D33) -> -15860 | E34: =SUM(E30:E33) -> -17050 | F34: =IFERROR((D34-E34)/ABS(E34),"") -> 0.069794721 | G34: 🔑
B35: Produits financiers | C35: Investissement | D35: 840 | E35: 620 | F35: =IFERROR((D35-E35)/ABS(E35),"") -> 0.35483871 | G35: IFRS 18
B36: Charges d'intérêts | C36: Financement | D36: -3696 | E36: -3875 | F36: =IFERROR((D36-E36)/ABS(E36),"") -> 0.046193548 | G36: IFRS 18
B37: Charge d'impôt (IS) | C37: Impôts | D37: -6125 | E37: -5200 | F37: =IFERROR((D37-E37)/ABS(E37),"") -> -0.17788462 | G37: IAS 12
B38: RÉSULTAT NET | D38: =D34+D35+D36+D37 -> -24841 | E38: =E34+E35+E36+E37 -> -25505 | F38: =IFERROR((D38-E38)/ABS(E38),"") -> 0.026034111 | G38: 🏆

Sheet UK_Filiale
B2: 🇬🇧 UK_Filiale – FILIALE ROYAUME-UNI · Exercice 2025-2026 (GBP)
B4: ⚙️ PARAMÈTRES ENTITÉ
B5: Entité : | C5: UK_Filiale
B6: Pays / Devise : | C6: Royaume-Uni · GBP (£) → Taux clôt. 1.1650 EUR/GBP
B7: % Détention : | C7: 0.8
B8: Méthode : | C8: Intégration Globale
B9: Taux de clôture : | C9: 1.1650 (GBP/EUR)
B10: Taux moyen : | C10: 1.1520 (GBP/EUR)
B11: Secteur : | C11: Technologies & Digital
B13: BILAN LOCAL (en k£) | I13: 🔄 CONVERSION EN EUR (pour consolidation)
B14: Poste IFRS | C14: Compte | D14: N (2025) | E14: N-1 (2024) | F14: Δ | G14: Note | I14: Poste | J14: Taux utilisé | K14: Local | L14: Converti EUR | M14: Méthode
B15: ACTIFS NON COURANTS | I15: Actifs/Passifs | J15: Taux clôture | K15: 1 | L15: 1.165 | M15: IAS 21 §23
B16: Immobilisations incorporelles | C16: 21xx | D16: 45000 | E16: 41000 | F16: =D16-E16 -> 4000 | I16: P&L / Charges | J16: Taux moyen | K16: 1 | L16: 1.152 | M16: IAS 21 §39
B17: Immobilisations corporelles (PP&E) | C17: 22xx | D17: 68000 | E17: 65000 | F17: =D17-E17 -> 3000 | I17: Capitaux propres | J17: Taux historique | K17: 1 | L17: 1 | M17: IAS 21 §39
B18: Impôts différés actifs & autres | C18: 274x | D18: 5200 | E18: 4800 | F18: =D18-E18 -> 400 | I18: Écart de conversion | J18: Différence | M18: OCI (IAS 21)
B19: TOTAL ACTIFS NON COURANTS | D19: =SUM(D16:D18) -> 118200 | E19: =SUM(E16:E18) -> 110800 | F19: =D19-E19 -> 7400
B20: ACTIFS COURANTS
B21: Stocks | C21: 31xx | D21: 18000 | E21: 16500 | F21: =D21-E21 -> 1500
B22: Créances clients | C22: 411x | D22: 52000 | E22: 47000 | F22: =D22-E22 -> 5000
B23: Créances interco | C23: 451x | D23: 18000 | E23: 14200 | F23: =D23-E23 -> 3800 | G23: ⚠️ ELIM
B24: Trésorerie | C24: 512x | D24: 38000 | E24: 32000 | F24: =D24-E24 -> 6000
B25: TOTAL ACTIFS COURANTS | D25: =SUM(D21:D24) -> 126000 | E25: =SUM(E21:E24) -> 109700 | F25: =D25-E25 -> 16300
B26: TOTAL ACTIF | D26: =D19+D25 -> 244200 | E26: =E19+E25 -> 220500 | F26: =D26-E26 -> 23700 | G26: ✔
B28: COMPTE DE RÉSULTAT LOCAL – IFRS 18 (k monnaie locale)
B29: Poste | C29: Cat. IFRS 18 | D29: N (2025) | E29: N-1 (2024) | F29: Δ % | G29: Note
B30: Chiffre d'affaires | C30: Opérationnel | D30: 142000 | E30: 128000 | F30: =IFERROR((D30-E30)/ABS(E30),"") -> 0.109375 | G30: IFRS 15
B31: Achats & charges opérat. | C31: Opérationnel | D31: -106800 | E31: -98600 | F31: =IFERROR((D31-E31)/ABS(E31),"") -> -0.0831643
B32: Charges de personnel | C32: Opérationnel | D32: -31240 | E32: -28160 | F32: =IFERROR((D32-E32)/ABS(E32),"") -> -0.109375
B33: Amortissements | C33: Opérationnel | D33: -7100 | E33: -6400 | F33: =IFERROR((D33-E33)/ABS(E33),"") -> -0.109375
B34: RÉSULTAT OPÉRATIONNEL (EBIT) | C34: Opérationnel | D34: =SUM(D30:D33) -> -3140 | E34: =SUM(E30:E33) -> -5160 | F34: =IFERROR((D34-E34)/ABS(E34),"") -> 0.39147287 | G34: 🔑
B35: Produits financiers | C35: Investissement | D35: 710 | E35: 512 | F35: =IFERROR((D35-E35)/ABS(E35),"") -> 0.38671875 | G35: IFRS 18
B36: Charges d'intérêts | C36: Financement | D36: -3124 | E36: -3200 | F36: =IFERROR((D36-E36)/ABS(E36),"") -> 0.02375 | G36: IFRS 18
B37: Charge d'impôt (IS) | C37: Impôts | D37: -7550 | E37: -6350 | F37: =IFERROR((D37-E37)/ABS(E37),"") -> -0.18897638 | G37: IAS 12
B38: RÉSULTAT NET | D38: =D34+D35+D36+D37 -> -13104 | E38: =E34+E35+E36+E37 -> -14198 | F38: =IFERROR((D38-E38)/ABS(E38),"") -> 0.077053106 | G38: 🏆

Sheet US_Filiale
B2: 🇺🇸 US_Filiale – FILIALE ÉTATS-UNIS · Exercice 2025-2026 (USD)
B4: ⚙️ PARAMÈTRES ENTITÉ
B5: Entité : | C5: US_Filiale
B6: Pays / Devise : | C6: États-Unis · USD ($) → Taux clôt. 0.9180 EUR/USD
B7: % Détention : | C7: 0.75
B8: Méthode : | C8: Intégration Globale
B9: Taux de clôture : | C9: 0.9180 (USD/EUR)
B10: Taux moyen : | C10: 0.9250 (USD/EUR)
B11: Secteur : | C11: Distribution & Retail
B13: BILAN LOCAL (en k$) | I13: 🔄 CONVERSION EN EUR (pour consolidation)
B14: Poste IFRS | C14: Compte | D14: N (2025) | E14: N-1 (2024) | F14: Δ | G14: Note | I14: Poste | J14: Taux utilisé | K14: Local | L14: Converti EUR | M14: Méthode
B15: ACTIFS NON COURANTS | I15: Actifs/Passifs | J15: Taux clôture | K15: 1 | L15: 0.918 | M15: IAS 21 §23
B16: Immobilisations incorporelles | C16: 21xx | D16: 12000 | E16: 11500 | F16: =D16-E16 -> 500 | I16: P&L / Charges | J16: Taux moyen | K16: 1 | L16: 0.925 | M16: IAS 21 §39
B17: Immobilisations corporelles (PP&E) | C17: 22xx | D17: 110000 | E17: 105000 | F17: =D17-E17 -> 5000 | I17: Capitaux propres | J17: Taux historique | K17: 1 | L17: 1 | M17: IAS 21 §39
B18: Impôts différés actifs & autres | C18: 274x | D18: 5200 | E18: 4800 | F18: =D18-E18 -> 400 | I18: Écart de conversion | J18: Différence | M18: OCI (IAS 21)
B19: TOTAL ACTIFS NON COURANTS | D19: =SUM(D16:D18) -> 127200 | E19: =SUM(E16:E18) -> 121300 | F19: =D19-E19 -> 5900
B20: ACTIFS COURANTS
B21: Stocks | C21: 31xx | D21: 71000 | E21: 65000 | F21: =D21-E21 -> 6000
B22: Créances clients | C22: 411x | D22: 44000 | E22: 41000 | F22: =D22-E22 -> 3000
B23: Créances interco | C23: 451x | D23: 8500 | E23: 7200 | F23: =D23-E23 -> 1300 | G23: ⚠️ ELIM
B24: Trésorerie | C24: 512x | D24: 31000 | E24: 27000 | F24: =D24-E24 -> 4000
B25: TOTAL ACTIFS COURANTS | D25: =SUM(D21:D24) -> 154500 | E25: =SUM(E21:E24) -> 140200 | F25: =D25-E25 -> 14300
B26: TOTAL ACTIF | D26: =D19+D25 -> 281700 | E26: =E19+E25 -> 261500 | F26: =D26-E26 -> 20200 | G26: ✔
B28: COMPTE DE RÉSULTAT LOCAL – IFRS 18 (k monnaie locale)
B29: Poste | C29: Cat. IFRS 18 | D29: N (2025) | E29: N-1 (2024) | F29: Δ % | G29: Note
B30: Chiffre d'affaires | C30: Opérationnel | D30: 195000 | E30: 178000 | F30: =IFERROR((D30-E30)/ABS(E30),"") -> 0.095505618 | G30: IFRS 15
B31: Achats & charges opérat. | C31: Opérationnel | D31: -169000 | E31: -156200 | F31: =IFERROR((D31-E31)/ABS(E31),"") -> -0.081946223
B32: Charges de personnel | C32: Opérationnel | D32: -42900 | E32: -39160 | F32: =IFERROR((D32-E32)/ABS(E32),"") -> -0.095505618
B33: Amortissements | C33: Opérationnel | D33: -9750 | E33: -8900 | F33: =IFERROR((D33-E33)/ABS(E33),"") -> -0.095505618
B34: RÉSULTAT OPÉRATIONNEL (EBIT) | C34: Opérationnel | D34: =SUM(D30:D33) -> -26650 | E34: =SUM(E30:E33) -> -26260 | F34: =IFERROR((D34-E34)/ABS(E34),"") -> -0.014851485 | G34: 🔑
B35: Produits financiers | C35: Investissement | D35: 975 | E35: 712 | F35: =IFERROR((D35-E35)/ABS(E35),"") -> 0.36938202 | G35: IFRS 18
B36: Charges d'intérêts | C36: Financement | D36: -4290 | E36: -4450 | F36: =IFERROR((D36-E36)/ABS(E36),"") -> 0.035955056 | G36: IFRS 18
B37: Charge d'impôt (IS) | C37: Impôts | D37: -5250 | E37: -4450 | F37: =IFERROR((D37-E37)/ABS(E37),"") -> -0.17977528 | G37: IAS 12
B38: RÉSULTAT NET | D38: =D34+D35+D36+D37 -> -35215 | E38: =E34+E35+E36+E37 -> -34448 | F38: =IFERROR((D38-E38)/ABS(E38),"") -> -0.022265444 | G38: 🏆

Sheet SG_Filiale
B2: 🇸🇬 SG_Filiale – FILIALE SINGAPOUR · Exercice 2025-2026 (SGD)
B4: ⚙️ PARAMÈTRES ENTITÉ
B5: Entité : | C5: SG_Filiale
B6: Pays / Devise : | C6: Singapour · SGD ($SG) → Taux clôt. 0.6780 EUR/SGD
B7: % Détention : | C7: 0.6
B8: Méthode : | C8: Intégration Globale
B9: Taux de clôture : | C9: 0.6780 (SGD/EUR)
B10: Taux moyen : | C10: 0.6820 (SGD/EUR)
B11: Secteur : | C11: Finance & Investissement
B13: BILAN LOCAL (en kSGD) | I13: 🔄 CONVERSION EN EUR (pour consolidation)
B14: Poste IFRS | C14: Compte | D14: N (2025) | E14: N-1 (2024) | F14: Δ | G14: Note | I14: Poste | J14: Taux utilisé | K14: Local | L14: Converti EUR | M14: Méthode
B15: ACTIFS NON COURANTS | I15: Actifs/Passifs | J15: Taux clôture | K15: 1 | L15: 0.678 | M15: IAS 21 §23
B16: Immobilisations incorporelles | C16: 21xx | D16: 28000 | E16: 26000 | F16: =D16-E16 -> 2000 | I16: P&L / Charges | J16: Taux moyen | K16: 1 | L16: 0.682 | M16: IAS 21 §39
B17: Immobilisations corporelles (PP&E) | C17: 22xx | D17: 42000 | E17: 40000 | F17: =D17-E17 -> 2000 | I17: Capitaux propres | J17: Taux historique | K17: 1 | L17: 1 | M17: IAS 21 §39
B18: Impôts différés actifs & autres | C18: 274x | D18: 5200 | E18: 4800 | F18: =D18-E18 -> 400 | I18: Écart de conversion | J18: Différence | M18: OCI (IAS 21)
B19: TOTAL ACTIFS NON COURANTS | D19: =SUM(D16:D18) -> 75200 | E19: =SUM(E16:E18) -> 70800 | F19: =D19-E19 -> 4400
B20: ACTIFS COURANTS
B21: Stocks | C21: 31xx | D21: 5000 | E21: 4500 | F21: =D21-E21 -> 500
B22: Créances clients | C22: 411x | D22: 21000 | E22: 18500 | F22: =D22-E22 -> 2500
B23: Créances interco | C23: 451x | D23: 9200 | E23: 7800 | F23: =D23-E23 -> 1400 | G23: ⚠️ ELIM
B24: Trésorerie | C24: 512x | D24: 28000 | E24: 24000 | F24: =D24-E24 -> 4000
B25: TOTAL ACTIFS COURANTS | D25: =SUM(D21:D24) -> 63200 | E25: =SUM(E21:E24) -> 54800 | F25: =D25-E25 -> 8400
B26: TOTAL ACTIF | D26: =D19+D25 -> 138400 | E26: =E19+E25 -> 125600 | F26: =D26-E26 -> 12800 | G26: ✔
B28: COMPTE DE RÉSULTAT LOCAL – IFRS 18 (k monnaie locale)
B29: Poste | C29: Cat. IFRS 18 | D29: N (2025) | E29: N-1 (2024) | F29: Δ % | G29: Note
B30: Chiffre d'affaires | C30: Opérationnel | D30: 88000 | E30: 79000 | F30: =IFERROR((D30-E30)/ABS(E30),"") -> 0.11392405 | G30: IFRS 15
B31: Achats & charges opérat. | C31: Opérationnel | D31: -70600 | E31: -64900 | F31: =IFERROR((D31-E31)/ABS(E31),"") -> -0.087827427
B32: Charges de personnel | C32: Opérationnel | D32: -19360 | E32: -17380 | F32: =IFERROR((D32-E32)/ABS(E32),"") -> -0.11392405
B33: Amortissements | C33: Opérationnel | D33: -4400 | E33: -3950 | F33: =IFERROR((D33-E33)/ABS(E33),"") -> -0.11392405
B34: RÉSULTAT OPÉRATIONNEL (EBIT) | C34: Opérationnel | D34: =SUM(D30:D33) -> -6360 | E34: =SUM(E30:E33) -> -7230 | F34: =IFERROR((D34-E34)/ABS(E34),"") -> 0.12033195 | G34: 🔑
B35: Produits financiers | C35: Investissement | D35: 440 | E35: 316 | F35: =IFERROR((D35-E35)/ABS(E35),"") -> 0.39240506 | G35: IFRS 18
B36: Charges d'intérêts | C36: Financement | D36: -1936 | E36: -1975 | F36: =IFERROR((D36-E36)/ABS(E36),"") -> 0.019746835 | G36: IFRS 18
B37: Charge d'impôt (IS) | C37: Impôts | D37: -3100 | E37: -2525 | F37: =IFERROR((D37-E37)/ABS(E37),"") -> -0.22772277 | G37: IAS 12
B38: RÉSULTAT NET | D38: =D34+D35+D36+D37 -> -10956 | E38: =E34+E35+E36+E37 -> -11414 | F38: =IFERROR((D38-E38)/ABS(E38),"") -> 0.040126161 | G38: 🏆

Sheet ELIM
B2: 🔄 ELIM – ÉCRITURES D'ÉLIMINATION INTERCOMPAGNIES & INTRAGROUPE · Exercice 2025-2026
B4: 1. TRANSACTIONS INTERCOMPAGNIES À ÉLIMINER
B5: Type | C5: Entité Vendeuse | D5: Entité Acheteuse | E5: Poste Actif | F5: Poste Passif | G5: Montant local | H5: Devise | I5: Taux | J5: Montant EUR k€ | K5: Référence | L5: Statut
B6: Ventes IC marchandises | C6: FR_ParentCo | D6: DE_Filiale | E6: Créances IC | F6: Dettes IC | G6: 18500 | H6: EUR | I6: 1 | J6: 18500 | K6: IC-2025-001 | L6: ✅ Validé
B7: Ventes IC marchandises | C7: FR_ParentCo | D7: UK_Filiale | E7: Créances IC | F7: Dettes IC | G7: 12400 | H7: GBP | I7: 1.165 | J7: 14446 | K7: IC-2025-002 | L7: ✅ Validé
B8: Ventes IC services (management fees) | C8: FR_ParentCo | D8: US_Filiale | E8: Créances IC | F8: Dettes IC | G8: 8500 | H8: USD | I8: 0.918 | J8: 7803 | K8: IC-2025-003 | L8: ✅ Validé
B9: Prêt interco | C9: FR_ParentCo | D9: SG_Filiale | E9: Créance fin. IC | F9: Dette fin. IC | G9: 5200 | H9: SGD | I9: 0.678 | J9: 3526 | K9: IC-2025-004 | L9: ✅ Validé
B10: Dividendes IC reçus | C10: DE_Filiale | D10: FR_ParentCo | E10: Produits financ. | F10: Dividendes versés | G10: 4200 | H10: EUR | I10: 1 | J10: 4200 | K10: IC-2025-005 | L10: ✅ Validé
B11: Dividendes IC reçus | C11: UK_Filiale | D11: FR_ParentCo | E11: Produits financ. | F11: Dividendes versés | G11: 2800 | H11: GBP | I11: 1.165 | J11: 3262 | K11: IC-2025-006 | L11: ⚠️ À vérifier
B12: Provision IC (risque) | C12: FR_ParentCo | D12: SG_Filiale | E12: Provision actif | F12: Risque passif | G12: 1500 | H12: EUR | I12: 1 | J12: 1500 | K12: IC-2025-007 | L12: ✅ Validé
B13: TOTAL ÉLIMINATIONS IC | J13: =SUM(I6:I12) -> 6.926 | L13: =COUNTA(K6:K12)&" lignes" -> 7 lignes
B15: 2. ÉLIMINATION DES TITRES DE PARTICIPATION & GOODWILL
B16: Filiale | C16: % Acq. | D16: Prix acquisition | E16: Actif net juste val. | F16: Goodwill brut | G16: Dépréciation GW cumulée | H16: Goodwill net | I16: Intérêts minoritaires | J16: Méthode IFRS 3 | K16: Date acq. | L16: Statut
B17: DE_Filiale | C17: 1 | D17: 85000 | E17: 62000 | F17: =D17-E17 -> 23000 | G17: 3500 | H17: =F17-G17 -> 19500 | I17: 0 | J17: IFRS 3 – Regroupement | K17: 43472 | L17: ✅
B18: UK_Filiale | C18: 0.8 | D18: 72000 | E18: 48500 | F18: =D18-E18 -> 23500 | G18: 4200 | H18: =F18-G18 -> 19300 | I18: 12400 | J18: IFRS 3 – Regroupement | K18: 15/03/2020 | L18: ✅
B19: US_Filiale | C19: 0.75 | D19: 95000 | E19: 71000 | F19: =D19-E19 -> 24000 | G19: 5800 | H19: =F19-G19 -> 18200 | I19: 18200 | J19: IFRS 3 – Regroupement | K19: 44197 | L19: ✅
B20: SG_Filiale | C20: 0.6 | D20: 38000 | E20: 28500 | F20: =D20-E20 -> 9500 | G20: 1200 | H20: =F20-G20 -> 8300 | I20: 7600 | J20: IFRS 3 – Regroupement | K20: 44570 | L20: ✅
B21: TOTAL | D21: =SUM(D17:D20) -> 290000 | E21: =SUM(E17:E20) -> 210000 | F21: =SUM(F17:F20) -> 80000 | G21: =SUM(G17:G20) -> 14700 | H21: =SUM(H17:H20) -> 65300 | I21: =SUM(I17:I20) -> 38200
B23: 3. ÉLIMINATION DES PROFITS INTERNES (Stocks & Actifs)
B24: Actif | C24: Entité vendeuse | D24: Entité acheteuse | E24: Coût revient | F24: Prix vente IC | G24: Marge IC | H24: Impact bilan (stock)
B25: Stock marchandises DE | C25: FR_ParentCo | D25: DE_Filiale | E25: 14800 | F25: 18500 | G25: =G25-F25 -> 0 | H25: =H25 -> 0
B26: Stock matières UK | C26: FR_ParentCo | D26: UK_Filiale | E26: 9800 | F26: 12400 | G26: =G26-F26 -> 0 | H26: =H26 -> 0
B27: TOTAL ÉLIM. PROFITS INTERNES | E27: =SUM(F25:F26) -> 30900 | F27: =SUM(G25:G26) -> 0 | G27: =SUM(H25:H26) -> 0 | H27: =SUM(I25:I26) -> 0
B29: 4. RÉCONCILIATION IC – CONTRÔLE DÉBIT/CRÉDIT
B30: Poste | C30: Actif IC total | D30: Passif IC total | E30: Écart (doit = 0) | F30: Statut
B31: Créances / Dettes commerciales IC | C31: 48900 | D31: 48900 | E31: =C31-D31 -> 0 | F31: =IF(E31=0,"✅ OK","⚠️ ÉCART") -> ✅ OK
B32: Prêts / Emprunts IC financiers | C32: 5200 | D32: 5200 | E32: =C32-D32 -> 0 | F32: =IF(E32=0,"✅ OK","⚠️ ÉCART") -> ✅ OK
B33: Dividendes IC | C33: 7462 | D33: 7462 | E33: =C33-D33 -> 0 | F33: =IF(E33=0,"✅ OK","⚠️ ÉCART") -> ✅ OK
B34: TOTAL CONTRÔLE | C34: =SUM(C31:C33) -> 61562 | D34: =SUM(D31:D33) -> 61562 | E34: =C34-D34 -> 0 | F34: =IF(E34=0,"✅ ÉQUILIBRÉ","🚨 REVOIR") -> ✅ ÉQUILIBRÉ

Sheet CONSOL_BILAN
B2: 📊 BILAN CONSOLIDÉ – GROUPE MULTINATIONAL · IFRS · Exercice 2025-2026 (en k€)
B3: ⚠️ Conversion IAS 21 : UK×1.1650 · US×0.9180 · SG×0.6780 (taux clôture) | Note : données converties en EUR avant agrégation
B4: Poste IFRS | C4: FR_ParentCo | D4: DE_Filiale (EUR) | E4: UK_Filiale (EUR) | F4: US_Filiale (EUR) | G4: SG_Filiale (EUR) | H4: AGRÉGÉ BRUT | I4: ÉLIMINATIONS | J4: CONSOLIDÉ N | K4: CONSOLIDÉ N-1 | L4: Δ %
B5: ACTIFS NON COURANTS | H5: =SUM(C5:G5) -> 0 | J5: =SUM(C5:H5) -> 0
B6: Goodwill net (IFRS 3) | C6: 61000 | D6: 20000 | E6: 40800 | F6: 16708 | G6: 5627 | H6: =SUM(C6:G6) -> 144135 | I6: -85000 | J6: =H6+I6 -> 59135 | K6: 85000 | L6: =IFERROR((J6-K6)/ABS(K6),"") -> -0.30429412
B7: Autres immobi. incorporelles | C7: 18000 | D7: 14500 | E7: 47765 | F7: 9180 | G7: 16817 | H7: =SUM(C7:G7) -> 106262 | I7: 0 | J7: =H7+I7 -> 106262 | K7: 97000 | L7: =IFERROR((J7-K7)/ABS(K7),"") -> 0.095484536
B8: Immobilisations corporelles | C8: 142000 | D8: 95000 | E8: 79220 | F8: 100980 | G8: 28476 | H8: =SUM(C8:G8) -> 445676 | I8: 0 | J8: =H8+I8 -> 445676 | K8: 418000 | L8: =IFERROR((J8-K8)/ABS(K8),"") -> 0.066210526
B9: Actifs droits d'utilisation (IFRS 16) | C9: 28500 | D9: 12000 | E9: 20970 | F9: 20196 | G9: 4068 | H9: =SUM(C9:G9) -> 85734 | I9: 0 | J9: =H9+I9 -> 85734 | K9: 78000 | L9: =IFERROR((J9-K9)/ABS(K9),"") -> 0.099153846
B10: Impôts différés actifs | C10: 12400 | D10: 5200 | E10: 7922 | F10: 8446 | G10: 2373 | H10: =SUM(C10:G10) -> 36341 | I10: 0 | J10: =H10+I10 -> 36341 | K10: 32000 | L10: =IFERROR((J10-K10)/ABS(K10),"") -> 0.13565625
B11: Autres actifs non courants | C11: 8500 | D11: 4800 | E11: 6058 | F11: 6885 | G11: 1898 | H11: =SUM(C11:G11) -> 28141 | I11: 0 | J11: =H11+I11 -> 28141 | K11: 25000 | L11: =IFERROR((J11-K11)/ABS(K11),"") -> 0.12564
B12: TOTAL ACTIFS NON COURANTS | C12: =SUM(C6:C11) -> 270400 | D12: =SUM(D6:D11) -> 151500 | E12: =SUM(E6:E11) -> 202735 | F12: =SUM(F6:F11) -> 162395 | G12: =SUM(G6:G11) -> 59259 | H12: =SUM(H6:H11) -> 846289 | I12: =SUM(I6:I11) -> -85000 | J12: =SUM(J6:J11) -> 761289 | K12: 720000 | L12: =IFERROR((J12-K12)/ABS(K12),"") -> 0.057345833
B13: ACTIFS COURANTS
B14: Stocks & en-cours | C14: 45200 | D14: 62000 | E14: 20970 | F14: 65178 | G14: 3390 | H14: =SUM(C14:G14) -> 196738 | I14: 0 | J14: =H14+I14 -> 196738 | K14: 188000 | L14: =IFERROR((J14-K14)/ABS(K14),"") -> 0.046478723
B15: Créances clients | C15: 67800 | D15: 38000 | E15: 60580 | F15: 40392 | G15: 14238 | H15: =SUM(C15:G15) -> 221010 | I15: 0 | J15: =H15+I15 -> 221010 | K15: 200000 | L15: =IFERROR((J15-K15)/ABS(K15),"") -> 0.10505
B16: Créances interco. (éliminées) | C16: 23500 | D16: 12500 | E16: 20970 | F16: 7803 | G16: 6240 | H16: =SUM(C16:G16) -> 71013 | I16: -70013 | J16: =H16+I16 -> 1000 | K16: 0 | L16: =IFERROR((J16-K16)/ABS(K16),"")
B17: Autres créances & CCA | C17: 8900 | D17: 6200 | E17: 9282 | F17: 8262 | G17: 2712 | H17: =SUM(C17:G17) -> 35356 | I17: 0 | J17: =H17+I17 -> 35356 | K17: 32000 | L17: =IFERROR((J17-K17)/ABS(K17),"") -> 0.104875
B18: Trésorerie & équivalents (IAS 7) | C18: 54300 | D18: 24000 | E18: 44270 | F18: 28458 | G18: 18984 | H18: =SUM(C18:G18) -> 170012 | I18: 0 | J18: =H18+I18 -> 170012 | K18: 158000 | L18: =IFERROR((J18-K18)/ABS(K18),"") -> 0.076025316
B19: TOTAL ACTIFS COURANTS | C19: =SUM(C14:C18) -> 199700 | D19: =SUM(D14:D18) -> 142700 | E19: =SUM(E14:E18) -> 156072 | F19: =SUM(F14:F18) -> 150093 | G19: =SUM(G14:G18) -> 45564 | H19: =SUM(H14:H18) -> 694129 | I19: =SUM(I14:I18) -> -70013 | J19: =SUM(J14:J18) -> 624116 | K19: 578000 | L19: =IFERROR((J19-K19)/ABS(K19),"") -> 0.079785467
B20: 🔷 TOTAL ACTIF | C20: =C12+C19 -> 470100 | D20: =D12+D19 -> 294200 | E20: =E12+E19 -> 358807 | F20: =F12+F19 -> 312488 | G20: =G12+G19 -> 104823 | H20: =H12+H19 -> 1540418 | I20: =I12+I19 -> -155013 | J20: =J12+J19 -> 1385405 | K20: 1298000 | L20: =IFERROR((J20-K20)/ABS(K20),"") -> 0.067338213
B22: CAPITAUX PROPRES (CONSOLIDÉS)
B23: Capital social & primes | C23: 178500 | D23: 62000 | E23: 52425 | F23: 53265 | G23: 10170 | H23: =SUM(C23:G23) -> 356360 | I23: -265000 | J23: =H23+I23 -> 91360
B24: Résultat consolidé (part groupe) | C24: 32800 | D24: 18500 | E24: 26096 | F24: 13586 | G24: 6036 | H24: =SUM(C24:G24) -> 97018 | I24: 0 | J24: =H24+I24 -> 97018
B25: Autres réserves & OCI | C25: -4200 | D25: 2800 | E25: 5823 | F25: 4590 | G25: 1356 | H25: =SUM(C25:G25) -> 10369 | I25: 0 | J25: =H25+I25 -> 10369
B26: Écart de conversion (IAS 21) | C26: 0 | D26: 0 | E26: -3200 | F26: -2100 | G26: -800 | H26: =SUM(C26:G26) -> -6100 | I26: 0 | J26: =PQ_TAUX_CHANGE!H50 -> 0
B27: Intérêts minoritaires (NCI – IFRS 10) | C27: 18700 | D27: 0 | E27: 15856 | F27: 18812 | G27: 7564 | H27: =SUM(C27:G27) -> 60932 | I27: 0 | J27: =H27+I27 -> 60932
B28: TOTAL CAPITAUX PROPRES | C28: =SUM(C23:C27) -> 225800 | D28: =SUM(D23:D27) -> 83300 | E28: =SUM(E23:E27) -> 97000 | F28: =SUM(F23:F27) -> 88153 | G28: =SUM(G23:G27) -> 24326 | H28: =SUM(H23:H27) -> 518579 | I28: =SUM(I23:I27) -> -265000 | J28: =SUM(J23:J27) -> 259679 | K28: 232200 | L28: =IFERROR((J28-K28)/ABS(K28),"") -> 0.11834195
B29: PASSIFS NON COURANTS
B30: Emprunts & dettes LT (IFRS 9) | C30: 125000 | D30: 48000 | E30: 41773 | F30: 64260 | G30: 16254 | H30: =SUM(C30:G30) -> 295287 | I30: -5200 | J30: =H30+I30 -> 290087 | K30: 340000 | L30: =IFERROR((J30-K30)/ABS(K30),"") -> -0.14680294
B31: Dettes locatives LT (IFRS 16) | C31: 22800 | D31: 9500 | E31: 20970 | F31: 18360 | G31: 4068 | H31: =SUM(C31:G31) -> 75698 | I31: 0 | J31: =H31+I31 -> 75698
B32: Provisions risques LT (IAS 37) | C32: 15400 | D32: 7200 | E32: 8738 | F32: 6426 | G32: 2780 | H32: =SUM(C32:G32) -> 40544 | I32: 0 | J32: =H32+I32 -> 40544
B33: Impôts différés passifs (IAS 12) | C33: 18900 | D33: 9800 | E33: 11440 | F33: 9180 | G33: 3390 | H33: =SUM(C33:G33) -> 52710 | I33: 0 | J33: =H33+I33 -> 52710
B34: TOTAL PASSIFS NON COURANTS | C34: =SUM(C30:C33) -> 182100 | D34: =SUM(D30:D33) -> 74500 | E34: =SUM(E30:E33) -> 82921 | F34: =SUM(F30:F33) -> 98226 | G34: =SUM(G30:G33) -> 26492 | H34: =SUM(H30:H33) -> 464239 | I34: =SUM(I30:I33) -> -5200 | J34: =SUM(J30:J33) -> 459039 | K34: 440000 | L34: =IFERROR((J34-K34)/ABS(K34),"") -> 0.043270455
B35: PASSIFS COURANTS
B36: Dettes fournisseurs | C36: 38200 | D36: 22000 | E36: 26303 | F36: 31212 | G36: 9490 | H36: =SUM(C36:G36) -> 127205 | I36: 0 | J36: =H36+I36 -> 127205 | K36: 115000
B37: Dettes financières CT | C37: 28500 | D37: 15000 | E37: 17475 | F37: 18360 | G37: 6102 | H37: =SUM(C37:G37) -> 85437 | I37: 0 | J37: =H37+I37 -> 85437 | K37: 72000 | L37: =IFERROR((J37-K37)/ABS(K37),"") -> 0.186625
B38: Dettes interco. (éliminées) | C38: 21400 | D38: 11800 | E38: 18200 | F38: 7500 | G38: 5100 | H38: =SUM(C38:G38) -> 64000 | I38: -64000 | J38: =H38+I38 -> 0
B39: Autres dettes & PCA | C39: 12800 | D39: 7500 | E39: 8738 | F39: 7344 | G39: 2712 | H39: =SUM(C39:G39) -> 39094 | I39: 0 | J39: =H39+I39 -> 39094
B40: TOTAL PASSIFS COURANTS | C40: =SUM(C36:C39) -> 100900 | D40: =SUM(D36:D39) -> 56300 | E40: =SUM(E36:E39) -> 70716 | F40: =SUM(F36:F39) -> 64416 | G40: =SUM(G36:G39) -> 23404 | H40: =SUM(H36:H39) -> 315736 | I40: =SUM(I36:I39) -> -64000 | J40: =SUM(J36:J39) -> 251736 | K40: 243000 | L40: =IFERROR((J40-K40)/ABS(K40),"") -> 0.035950617
B41: 🔷 TOTAL PASSIF | C41: =C28+C34+C40 -> 508800 | D41: =D28+D34+D40 -> 214100 | E41: =E28+E34+E40 -> 250637 | F41: =F28+F34+F40 -> 250795 | G41: =G28+G34+G40 -> 74222 | H41: =H28+H34+H40 -> 1298554 | I41: =I28+I34+I40 -> -334200 | J41: =J28+J34+J40 -> 970454 | K41: 1298000 | L41: =IFERROR((J41-K41)/ABS(K41),"") -> -0.25234669
B42: Écart de consolidation (réconciliation PPA/NCI) | J42: =J20-J41 -> 414951
...

Sheet CONSOL_CR
B2: 📊 COMPTE DE RÉSULTAT CONSOLIDÉ – IFRS 18 · Groupe Multinational · Exercice 2025-2026 (en k€)
B3: 🔵 IFRS 18 impose 5 catégories obligatoires : ① Exploitation · ② Investissement · ③ Financement · ④ Impôts · ⑤ Activités abandonnées
B4: 💱 Taux de conversion appliqués (IAS 21) – Liés à PQ_TAUX_CHANGE
B5: Poste IFRS 18 | C5: Cat. | D5: FR_ParentCo | E5: DE_Filiale | F5: UK (EUR) ×1.1520 moy. | G5: US (EUR) ×0.9250 moy. | H5: SG (EUR) ×0.6820 moy. | I5: AGRÉGÉ | J5: ÉLIM. IC | K5: CONSOLIDÉ N | L5: CONSOLIDÉ N-1 | M5: Δ %
B6: ① EXPLOITATION (OPERATING)
B7: Chiffre d'affaires net | C7: Opérat. | D7: 285000 | E7: 168000 | F7: 163584 | G7: 180375 | H7: 60016 | I7: =SUM(D7:H7) -> 856975 | J7: -39900 | K7: =I7+J7 -> 817075 | L7: 820000 | M7: =IFERROR((K7-L7)/ABS(L7),"") -> -0.0035670732
B8: Variation de stocks | C8: Opérat. | D8: 1800 | E8: 2200 | F8: 1728 | G8: 2590 | H8: 341 | I8: =SUM(D8:H8) -> 8659 | J8: 0 | K8: =I8+J8 -> 8659 | L8: 8200 | M8: =IFERROR((K8-L8)/ABS(L8),"") -> 0.05597561
B9: Autres produits opérationnels | C9: Opérat. | D9: 3200 | E9: 1800 | F9: 2765 | G9: 2960 | H9: 818 | I9: =SUM(D9:H9) -> 11543 | J9: -1500 | K9: =I9+J9 -> 10043 | L9: 9500 | M9: =IFERROR((K9-L9)/ABS(L9),"") -> 0.057157895
B10: Achats & charges externes | C10: Opérat. | D10: -142000 | E10: -82000 | F10: -78336 | G10: -85100 | H10: -25916 | I10: =SUM(D10:H10) -> -413352 | J10: 28000 | K10: =I10+J10 -> -385352 | L10: -374000 | M10: =IFERROR((K10-L10)/ABS(L10),"") -> -0.030352941
B11: Charges de personnel | C11: Opérat. | D11: -68000 | E11: -45000 | F11: -43776 | G11: -48100 | H11: -15004 | I11: =SUM(D11:H11) -> -219880 | J11: 0 | K11: =I11+J11 -> -219880 | L11: -224000 | M11: =IFERROR((K11-L11)/ABS(L11),"") -> 0.018392857
B12: Amortissements (PP&E + IFRS 16) | C12: Opérat. | D12: -22000 | E12: -12000 | F12: -11290 | G12: -13135 | H12: -4228 | I12: =SUM(D12:H12) -> -62653 | J12: 0 | K12: =I12+J12 -> -62653 | L12: -64200 | M12: =IFERROR((K12-L12)/ABS(L12),"") -> 0.024096573
B13: Dotations aux provisions | C13: Opérat. | D13: -4500 | E13: -2800 | F13: -2534 | G13: -3237 | H13: -1023 | I13: =SUM(D13:H13) -> -14094 | J13: 0 | K13: =I13+J13 -> -14094 | L13: -14500 | M13: =IFERROR((K13-L13)/ABS(L13),"") -> 0.028
B14: 🔑 RÉSULTAT OPÉRATIONNEL (EBIT) | C14: IFRS 18 | D14: =SUM(D7:D13) -> 53500 | E14: =SUM(E7:E13) -> 30200 | F14: =SUM(F7:F13) -> 32141 | G14: =SUM(G7:G13) -> 36353 | H14: =SUM(H7:H13) -> 15004 | I14: =SUM(I7:I13) -> 167198 | J14: =SUM(J7:J13) -> -13400 | K14: =SUM(K7:K13) -> 153798 | L14: 161000 | M14: =IFERROR((K14-L14)/ABS(L14),"") -> -0.044732919
B15: ② INVESTISSEMENT (INVESTING)
B16: Dividendes reçus (hors exploitation) | C16: Invest. | D16: 4200 | E16: 0 | F16: 0 | G16: 0 | H16: 0 | I16: =SUM(D16:H16) -> 4200 | J16: -4200 | K16: =I16+J16 -> 0 | L16: 0 | M16: =IFERROR((K16-L16)/ABS(L16),"")
B17: Produits de cessions d'actifs | C17: Invest. | D17: 1500 | E17: 800 | F17: 691 | G17: 1110 | H17: 0 | I17: =SUM(D17:H17) -> 4101 | J17: 0 | K17: =I17+J17 -> 4101 | L17: 4800 | M17: =IFERROR((K17-L17)/ABS(L17),"") -> -0.145625
B18: Produits financiers sur placements | C18: Invest. | D18: 890 | E18: 420 | F18: 438 | G18: 481 | H18: 191 | I18: =SUM(D18:H18) -> 2420 | J18: 0 | K18: =I18+J18 -> 2420 | L18: 2400 | M18: =IFERROR((K18-L18)/ABS(L18),"") -> 0.0083333333
B19: RÉSULTAT INVESTISSEMENT | C19: IFRS 18 | D19: =SUM(D16:D18) -> 6590 | E19: =SUM(E16:E18) -> 1220 | F19: =SUM(F16:F18) -> 1129 | G19: =SUM(G16:G18) -> 1591 | H19: =SUM(H16:H18) -> 191 | I19: =SUM(I16:I18) -> 10721 | J19: =SUM(J16:J18) -> -4200 | K19: =SUM(K16:K18) -> 6521 | L19: 7200 | M19: =IFERROR((K19-L19)/ABS(L19),"") -> -0.094305556
B20: ③ FINANCEMENT (FINANCING)
B21: Charges d'intérêts (emprunts) | C21: Fin. | D21: -8200 | E21: -4500 | F21: -5990 | G21: -7215 | H21: -1910 | I21: =SUM(D21:H21) -> -27815 | J21: 0 | K21: =I21+J21 -> -27815 | L21: -31200 | M21: =IFERROR((K21-L21)/ABS(L21),"") -> 0.10849359
