Workbook
Name Input_SIREN: #REF!

Sheet Claude Log
A1: Turn # | B1: Date | C1: User Request | D1: Action Taken | E1: Details | F1: Outcome
A2: 1 | B2: 46086 | C2: Analyse complète du fichier pour détecter erreurs, laisser-aller et incohérences dans le simulateur d'analyse d'entreprise | D2: Audit intégral de 9 onglets : Données Brutes, Ratios, DCF, Analyse Approfondie, Dashboard, Benchmark, etc. | E2: Identifié : (1) Bilan déséquilibré -2,16M€ toutes années, (2) DCF avec Amortissements=Charges personnel=6,9M au lieu de 1,45M via lien Dashboard, (3) EBIT négatif -2,58M faussant toute la valorisation, (4) #NOM? en B43, (5) Sous-totaux flux trésorerie incorrects (copier-coller SUMIF Financement partout), (6) Waterfall ne boucle pas (cumulé E29 cassé), (7) Multiples hardcodés sans formule, (8) Table sensibilité statique | F2: Rapport complet remis à l'utilisateur avec 10+ erreurs critiques et recommandations de correction
A3: 2 | B3: 46086 | C3: Utilisateur confirme : corriger toutes les erreurs identifiées dans l'audit | D3: Corrections appliquées : (1) DCF C36 corrigé E45→amort, (2) B43 #NOM? fixé, (3) Sous-totaux flux nettoyés, (4) Waterfall E29 rétabli + notes alerte, (5) Table sensibilité dynamisée, (6) Fourchette valorisation harmonisée, (7) Notes sur multiples | E3: DCF : EV corrigée de 50,8M€ → 15,6M€ — Equity Value 11,5M€. Table sensibilité : 35 formules dynamiques remplacent les hardcodes. Flux tréso : sous-totaux parasites supprimés, seuls F58/F66/F69 conservés. Waterfall : chaînage E29 rétabli, notes d'alerte sur incohérence RN (1100k vs 1580k). Reste à corriger : bilan déséquilibré (2,16M€ — nécessite données manquantes du client). | F3: 7 corrections appliquées. Bilan non corrigé (données manquantes). Waterfall partiellement corrigé (écarts à recalibrer par l'utilisateur).
A4: 3 | B4: 46086 | C4: L'utilisateur souhaite réaliser une simulation complète en étant guidé pas à pas pour alimenter les données | D4: Plan de simulation en 6 étapes présenté : (1) Nom entreprise, (2) Données Brutes, (3) Scénarios, (4) WACC, (5) Projections DCF, (6) Multiples. Étape 1 validée (nom conservé). Étape 2 lancée — l'utilisateur veut modifier toutes les données brutes. | E4: Cartographie complète des cellules modifiables : K1 (nom), C2:E23 (bilan 3 ans), C35:E53 (CPC 3 ans), C58:E72 (flux 3 ans), C7:F9 Analyse Approf. (scénarios), C7:C13 + C27:C31 + C50 + C62 + C71:C73 DCF (hypothèses). Guide structuré envoyé pour la saisie du bilan (22 postes × 3 années). | F4: En attente des données bilan/CPC/flux de l'utilisateur. Étape 2A (Bilan) en cours.
A5: 4 | B5: 46086 | C5: L'utilisateur demande comment être sûr que les données financières qu'il va recevoir soient dans le même ordre que son tableau | D5: Explication des 3 méthodes : (1) envoyer les données brutes et laisser Claude mapper, (2) tableau de correspondance ligne par ligne, (3) upload fichier. Alerte sur saisie manuelle en cours (C3 possiblement erroné : 1,14M au lieu de 11,4M). | E5: L'utilisateur a commencé à modifier C2 (610k) et C3 (1 140 000 — possible erreur de zéro). Recommandation : envoyer la source comptable d'un bloc pour mapping automatique plutôt que saisie cellule par cellule. | F5: En attente du choix de méthode de saisie et des données de l'utilisateur.
A6: 5 | B6: 46086 | C6: L'utilisateur pense que certaines formules de l'onglet Données Brutes sont buguées (sélection sur C28, l'écart bilan) | D6: Audit complet de TOUTES les formules de l'onglet : variations F/G (22+19 postes), totaux actif/passif (C26:E27), contrôle bilan (C28:E28), sous-totaux flux (F58/F66/F69/F73), flux net (E73). Toutes les formules sont correctes. | E6: Le problème n'est pas les formules mais les données : écart bilan 2023=3,81M (aggravé par modif C2/C3), 2024=730k, 2025=2,16M. Il manque probablement un poste 'Report à nouveau' côté passif. Proposition : ajouter une ligne CP ou intégrer dans Réserves. | F6: Diagnostic livré. En attente décision utilisateur : ajouter 'Report à nouveau' ou intégrer dans Réserves.
A7: 6 | B7: 46086 | C7: L'utilisateur demande de se conformer aux normes comptables légales (PCG) en ajoutant le poste Report à nouveau pour équilibrer le bilan | D7: Ajout ligne 14 'Report à nouveau' (Capitaux Propres) conformément au PCG. Formule dynamique : =Actif Total − (Autres CP + Dettes). Correction formules écart C29/D29 après décalage. Mise à jour DCF C17 pour inclure E14 dans les CP. Vérification cascade complète sur tous les onglets. | E7: Report à nouveau calculé : 2023=3 810k, 2024=730k, 2025=2 160k. Bilan équilibré à 0€ pour les 3 années. DCF : CP passent de 10,23M à 12,39M, WACC ajusté de 6,51% à 6,70%, Equity Value = 10,85M€ (vs 11,48M avant). Toutes les refs inter-onglets vérifiées (Dashboard, Benchmark, Budget OK). Note ajoutée : remplacer par valeur réelle de la liasse fiscale. | F7: Bilan équilibré ✅ — PCG respecté. DCF recalculé. Prêt à reprendre la simulation étape 2.
A8: 7 | B8: 46086 | C8: L'utilisateur demande un audit complet de conformité PCG sur les calculs, formules et analyses du fichier | D8: Audit exhaustif PCG via Python : reconstitution des 8 SIG, vérification croisée CPC↔Bilan, contrôle de chaque ratio. 6 non-conformités identifiées dont 3 critiques. | E8: Non-conformités trouvées : (1) EBITDA omet Prod.stockée/immob/subventions (écart 540k), (2) RN CPC≠RN Bilan (2 115k vs 1 580k, écart 535k), (3) Marge Brute=Taux MCV (doublon), (4) SIG intermédiaires manquants (Production, VA, RCAI, R.exceptionnel), (5) Cap.remboursement utilise EBITDA au lieu de CAF, (6) DPO exclut Autres achats du dénominateur. | F8: Rapport complet livré. En attente décision utilisateur sur corrections à apporter.
A9: 8 | B9: 46086 | C9: L'utilisateur valide les corrections PCG à appliquer | D9: 5 corrections PCG appliquées : (1) RN bilan=RN CPC via formule dynamique, (2) EBE/EBITDA Dashboard+Ratios inclut Prod.stockée/immob/Subventions, (3) Marge Brute inclut Production, (4) DPO inclut Autres achats, (5) Cap.remboursement utilise CAF | E9: Résultats 2025 corrigés : RN=2 115k (vs 1 580k), EBE=4 770k (vs 4 320k), Marge EBITDA=14,7% (vs 13,3%), Marge Brute=52,2% (vs 51,1%), DPO=66,8j (vs 86,4j), CCC=100j (vs 80j), Cap.rembours.=2,76 ans (vs 2,41). Marge nette=6,5%, ROE=17,1%. DCF: EBITDA base=4 770k, FCFF 2025=2 190k, EV=15M, Equity=10,85M. | F9: Conformité PCG atteinte sur les 5 points identifiés. Il reste les SIG manquants (Production, VA, RCAI, R.except) qui sont un 'nice to have' mais non bloquant.
A10: 9 | B10: 46086 | C10: L'utilisateur demande s'il y a des erreurs sur la colonne D du DCF et la cellule C38. Il a aussi modifié C14/C15/D14 et C27 (syntaxe SOMME.SI). | D10: Audit colonne D et C38 : aucune erreur trouvée, formules toutes correctes. Correction de 2 erreurs introduites par l'utilisateur : (1) C27 en format texte après saisie SOMME.SI → remis en General + SUMIF, (2) C14 référence circulaire résolue en pointant sur les cellules individuelles au lieu de C27. | E10: C38=EBIT×IS=830k ✅. Colonne D : CA+5%, Marge EBITDA 15% normalisée, toutes formules correctes. C27 était formaté texte (SOMME.SI), converti en General+SUMIF. Bilan 2023 rééquilibré à 0€. | F10: DCF validé. Bilan 2023 rééquilibré. Toutes erreurs résolues.
A11: 10 | B11: 46086 | C11: Automatiser l'onglet Analyse Approfondie avec des formules dynamiques et vérifier/corriger les erreurs | D11: 4 corrections majeures : (1) Waterfall 5B entièrement automatisé avec formules liées au Budget/Réel, (2) Table de sensibilité 5D — 35 cellules hardcodées remplacées par formules SUMIF, (3) G12/H12 corrigées (format texte @→nombre), (4) F55 changé de texte à nombre, (5) B53 dynamisé, (6) Colonne D Sens automatisée | E11: Waterfall : C23=Budget calculé (4 820k), C24:C30=écarts dynamiques depuis T_Budget, C31=Réel calculé (2 330k). Réconciliation parfaite : Budget + Σ écarts = Réel ✅. Sensibilité : formule = Tréso_base + CA×ΔCA − COGS×Inflation, toutes 35 valeurs identiques aux originales. G12/H12 : format texte @ empêchait l'évaluation des MIN/MAX — corrigé via Office.js. F55 : '0% (Base)' → 0 pour éviter #VALEUR! | F11: Onglet Analyse Approfondie entièrement automatisé. Sections 5A (scénarios), 5B (waterfall), 5C (trésorerie), 5D (sensibilité) toutes dynamiques. 0 erreurs restantes. Toutes les données se mettent à jour automatiquement si les Données Brutes changent.
A12: 11 | B12: 46086 | C12: Proposer des améliorations du Dashboard Interactif pour le rendre plus professionnel et compréhensif pour présentation COMEX | D12: Audit complet du Dashboard : 5 charts, 12 ratios, KPI cards, section ESG. Plan de refonte en 5 phases proposé à l'utilisateur. | E12: Phase 1: Reformater KPI cards + ajouter Trésorerie Nette. Phase 2: Colonne tendance YoY + réorganisation ratios + alertes raccourcies. Phase 3: Corriger source graphique Évolution 3 ans + ajouter Écart % sur Budget vs Réel. Phase 4: Synthèse exécutive textuelle + décomposition charges. Phase 5: Grouper données techniques pour masquage en présentation. | F12: Plan présenté, en attente validation utilisateur avant exécution.
A13: 12 | B13: 46086 | C13: Refonte complète du Dashboard Interactif pour présentation COMEX : visuels + contenu + nouveaux éléments | D13: Phase 1: KPI cards refondues (format M€, variations YoY, indicateurs secondaires). Phase 2: Synthèse exécutive dynamique (Forces/Vigilance/Actions). Phase 3: Nouveau chart doughnut Répartition Charges. Phase 4: Colonnes techniques groupées. Phase 5: Mise en forme conditionnelle ratios. | E13: KPI: B4=32,4M€ (+8,7%), C4=4,77M€ (marge 14,7%), D4=2,12M€ (+70k), E4=17,1% ROE, F4=116/150 pts. Sous-KPI: Tréso 1 950k, DIO/DSO, Marge Nette 6,5%, Z-Score 2,93, Verdict VERT. Synthèse: 4 lignes dynamiques. 6 charts total. Cols H:Q groupées. | F13: Dashboard refait pour COMEX. 6 graphiques, KPI cards enrichis, synthèse exécutive dynamique, données techniques masquées.
... A30: 30 | B30: 46095 | C30: Créer des sections pour calculer les écarts entre départements fonctionnels (Marketing, Compta, RH, SI, Autres) de façon lisible et professionnelle, avec des données réalistes. | D30: Créé Zone 8 complète dans ECARTS_BU (lignes 126-174) avec 4 sous-sections : 8A (détail charges par département Budget vs Réel, 10 postes x 5 départements), 8B (synthèse comparative avec effectifs et coût/ETP), 8C (KPI de pilotage : part FG, ratio CA, indice dérive), 8D (Top 5 postes à investiguer avec causes et actions). | E30: Données réalistes pour Acier Côte Ouest SAS (~43 ETP en fonctions support). Tous les Budget/Réel sont saisissables (en bleu). Formules dynamiques pour écarts EUR, %, sens, consolidé. Mise en forme professionnelle cohérente avec les zones existantes (même palette couleur par dept). Mise en forme conditionnelle Fav./Défav. Total frais généraux : Budget 4 021 k€, Réel 4 170 k€, écart +149 k€ (+3.7%). SI identifié en dérive (8.3%), Compta et RH maîtrisés. | F30: Zone 8 opérationnelle. Le SI est le département le plus en dérive (+78k€, 8.3%) principalement dû aux licences cloud et prestations cybersécurité. Le Marketing dépasse de +55k€ (6.9%). Compta légèrement sous-budget (-10.5k€). RH et Autres légèrement au-dessus. Toutes les formules fonctionnent sans erreur.

Sheet One-Pager
B2: ='Données Brutes'!L1&" — RAPPORT DE DIRECTION | Exercice 2025" -> Acier Côte Ouest SAS — RAPPORT DE DIRECTION | Exercice 2025
B3: Synthèse automatique · Données liées au modèle financier · Mise à jour: 2025
B4: 📊 SCORE GLOBAL | D4: 🚦 FEU TRICOLORE | F4: 💎 ENTERPRISE VALUE (DCF)
B5: ='Ratios & Indicateurs'!F90&" / 150" -> 121 / 150 | D5: ='Dashboard Interactif'!F6 -> Santé financière solide | F5: ='Valorisation DCF'!C58/Accueil!F27 -> 26.199447
B6: =TEXT('Ratios & Indicateurs'!F90/150*100,"0")&"% atteint" -> 81% atteint | D6: ='Ratios & Indicateurs'!G91 -> 0 | F6: =Accueil!F28&" — Enterprise Value DCF" -> M€ — Enterprise Value DCF
B7: =IF('Ratios & Indicateurs'!F90/150>=0.75,"✅ Santé financière solide",IF('Ratios & Indicateurs'!F90/150>=0.5,"⚠️ Vigilance requise","🔴 Risques élevés")) -> ✅ Santé financière solide | D7: Score >= 75% = VERT, >=50% = ORANGE, <50% = ROUGE | F7: ="WACC: "&TEXT('Valorisation DCF'!C22*100,"0,0")&"% | g: "&TEXT('Valorisation DCF'!C50*100,"0,0")&"%" -> WACC: 6,8% | g: 2,0%
B10: KPIs FINANCIERS CLES 2025
B11: Indicateur | C11: 2023 | D11: 2024 | E11: 2025 | F11: Norme | G11: Statut
B12: ="Chiffre d'Affaires ("&Accueil!F28&")" -> Chiffre d'Affaires (M€) | C12: ='Données Brutes'!D38 -> 28500000 | D12: ='Données Brutes'!E38 -> 29800000 | E12: ='Données Brutes'!F38 -> 32400000 | F12: Hausse | G12: =IF('Données Brutes'!F38>'Données Brutes'!E38,"Hausse","Baisse") -> Hausse
B13: ="EBITDA ("&Accueil!F28&")" -> EBITDA (M€) | C13: =(SUMIF('Données Brutes'!A38:A56,"Chiffre d'affaires net",'Données Brutes'!D38:D56)+SUMIF('Données Brutes'!A38:A56,"Production stockée",'Données Brutes'!D38:D56)+SUMIF('Données Brutes'!A38:A56,"Production immobilisée",'Données Brutes'!D38:D56)+SUMIF('Données Brutes'!A38:A56,"Subventions exploitation",'Données Brutes'!D38:D56))-(SUMIF('Données Brutes'!A38:A56,"Achats matières premières",'Données Brutes'!D38:D56)+SUMIF('Données Brutes'!A38:A56,"Variation stocks MP",'Données Brutes'!D38:D56)+SUMIF('Données Brutes'!A38:A56,"Autres achats & charges ext.",'Données Brutes'!D38:D56)+SUMIF('Données Brutes'!A38:A56,"Impôts & taxes",'Données Brutes'!D38:D56)+SUMIF('Données Brutes'!A38:A56,"Charges de personnel",'Données Brutes'!D38:D56)) -> 3980000 | D13: =(SUMIF('Données Brutes'!A38:A56,"Chiffre d'affaires net",'Données Brutes'!E38:E56)+SUMIF('Données Brutes'!A38:A56,"Production stockée",'Données Brutes'!E38:E56)+SUMIF('Données Brutes'!A38:A56,"Production immobilisée",'Données Brutes'!E38:E56)+SUMIF('Données Brutes'!A38:A56,"Subventions exploitation",'Données Brutes'!E38:E56))-(SUMIF('Données Brutes'!A38:A56,"Achats matières premières",'Données Brutes'!E38:E56)+SUMIF('Données Brutes'!A38:A56,"Variation stocks MP",'Données Brutes'!E38:E56)+SUMIF('Données Brutes'!A38:A56,"Autres achats & charges ext.",'Données Brutes'!E38:E56)+SUMIF('Données Brutes'!A38:A56,"Impôts & taxes",'Données Brutes'!E38:E56)+SUMIF('Données Brutes'!A38:A56,"Charges de personnel",'Données Brutes'!E38:E56)) -> 4225000 | E13: ='Dashboard Interactif'!C4 -> 4770000 | F13: > 15% CA | G13: ='Dashboard Interactif'!E18 -> 🔴 Critique
B14: Marge EBITDA | C14: ='Ratios & Indicateurs'!D24 -> 0.13964912 | D14: ='Ratios & Indicateurs'!E24 -> 0.14177852 | E14: ='Ratios & Indicateurs'!F24 -> 0.14722222 | F14: > 15% | G14: ='Dashboard Interactif'!E18 -> 🔴 Critique
B15: ROE | C15: ='Ratios & Indicateurs'!D27 -> 0.16694844 | D15: ='Ratios & Indicateurs'!E27 -> 0.20409182 | E15: ='Ratios & Indicateurs'!F27 -> 0.1597432 | F15: > 12% | G15: ='Dashboard Interactif'!E19 -> ✅ OK
B16: Altman Z-Score | C16: ='Ratios & Indicateurs'!D20 -> 2.7146526 | D16: ='Ratios & Indicateurs'!E20 -> 3.0062858 | E16: ='Ratios & Indicateurs'!F20 -> 2.9382453 | F16: > 2,99 | G16: ='Dashboard Interactif'!E16 -> ⚠️ Zone Grise
B17: Endettement (D/E) | C17: ='Ratios & Indicateurs'!D14 -> 0.95519865 | D17: ='Ratios & Indicateurs'!E14 -> 1.0888224 | E17: ='Ratios & Indicateurs'!F14 -> 0.93504532 | F17: < 1,0x | G17: ='Dashboard Interactif'!E15 -> ✅ OK
B18: Délai Clients (DSO) | C18: ='Ratios & Indicateurs'!D34 -> 53.789474 | D18: ='Ratios & Indicateurs'!E34 -> 56.342282 | E18: ='Ratios & Indicateurs'!F34 -> 57.453704 | F18: < 45j | G18: ='Dashboard Interactif'!E20 -> ⚠️ Long
B19: Cycle Trésorerie (CCC) | C19: ='Ratios & Indicateurs'!D37 -> 115.52797 | D19: ='Ratios & Indicateurs'!E37 -> 112.16613 | E19: ='Ratios & Indicateurs'!F37 -> 119.6444 | F19: < 60j | G19: ='Dashboard Interactif'!E21 -> 🔴 Critique
B21: 3 ALERTES CRITIQUES — SOURCE: BENCHMARK & ALERTES
B22: # | C22: Alerte | D22: Valeur | E22: Seuil | F22: Statut | G22: Action prioritaire
B23: 1 | C23: ="Point Mort depasse ("&TEXT('Ratios & Indicateurs'!F44,"0")&" j > 300 j)" -> Point Mort depasse (309 j > 300 j) | D23: ='Dashboard Interactif'!C22 -> 308.98187 | E23: < 300 j | F23: ='Dashboard Interactif'!E22 -> 🔴 Critique | G23: Audit charges fixes — Réduire coûts d'exploitation
B24: 2 | C24: ="CAPEX depasse budget de +"&TEXT(('Données Brutes'!D87-'Données Brutes'!C87)/'Données Brutes'!C87*100,"0")&"% ("&TEXT('Données Brutes'!D87/Accueil!F27,"0,0")&" "&Accueil!F28&" vs "&TEXT('Données Brutes'!C87/Accueil!F27,"0,0")&" "&Accueil!F28&")" -> CAPEX depasse budget de +14% (3,2 M€ vs 2,8 M€) | D24: ='Données Brutes'!F83 -> 0.056818182 | E24: > +10% | F24: CRITIQUE | G24: Revoir plan CAPEX 2026 — Validation DG
B25: 3 | C25: ="Marge EBITDA sous norme ("&TEXT('Ratios & Indicateurs'!F24*100,"0,0")&"% vs 15% cible)" -> Marge EBITDA sous norme (14,7% vs 15% cible) | D25: ='Ratios & Indicateurs'!F24 -> 0.14722222 | E25: > 15% | F25: ='Dashboard Interactif'!E18 -> 🔴 Critique | G25: Renégociation fournisseurs — Optimiser mix coûts
B27: WATERFALL CASH-FLOW — BRIDGE RESULTAT NET 2025 (Budget → Réel)
B28: Étape | C28: ="Montant ("&Accueil!F28&")" -> Montant (M€) | D28: Impact | E28: ="Cumulé ("&Accueil!F28&")" -> Cumulé (M€) | F28: Δ% vs Budget | G28: Commentaire
B29: ='Analyse Approfondie'!B22 -> Étape de réconciliation | C29: ='Analyse Approfondie'!C22 -> Montant (M€) | D29: ='Analyse Approfondie'!D22 -> Sens | E29: ='Analyse Approfondie'!E22 -> Cumulé (M€) | F29: ='Analyse Approfondie'!F22 -> Δ % vs Budget
B30: ='Analyse Approfondie'!B23 -> Budget Résultat Net | C30: ='Analyse Approfondie'!C23 -> 4820000 | D30: ='Analyse Approfondie'!D23 -> Référence | E30: ='Analyse Approfondie'!E23 -> 4820000 | F30: ='Analyse Approfondie'!F23 -> — | G30: Objectif initial 2025
B31: ='Analyse Approfondie'!B24 -> Écart CA (volume) | C31: ='Analyse Approfondie'!C24 -> -1600000 | D31: ='Analyse Approfondie'!D24 -> Défavorable | E31: ='Analyse Approfondie'!E24 -> 3220000 | F31: ='Analyse Approfondie'!F24 -> -0.33195021 | G31: CA réel < budget (−14,7%)
B32: ='Analyse Approfondie'!B25 -> Écart Matières premières | C32: ='Analyse Approfondie'!C25 -> -300000 | D32: ='Analyse Approfondie'!D25 -> Défavorable | E32: ='Analyse Approfondie'!E25 -> 2920000 | F32: ='Analyse Approfondie'!F25 -> -0.062240664 | G32: Hausse coût matières
B33: ='Analyse Approfondie'!B26 -> Écart Charges personnel | C33: ='Analyse Approfondie'!C26 -> -200000 | D33: ='Analyse Approfondie'!D26 -> Défavorable | E33: ='Analyse Approfondie'!E26 -> 2720000 | F33: ='Analyse Approfondie'!F26 -> -0.041493776 | G33: Recrutements suppl.
B34: ='Analyse Approfondie'!B27 -> Écart Charges externes | C34: ='Analyse Approfondie'!C27 -> -250000 | D34: ='Analyse Approfondie'!D27 -> Défavorable | E34: ='Analyse Approfondie'!E27 -> 2470000 | F34: ='Analyse Approfondie'!F27 -> -0.05186722 | G34: Prestataires > budget
B35: ='Analyse Approfondie'!B28 -> Écart Amortissements | C35: ='Analyse Approfondie'!C28 -> -150000 | D35: ='Analyse Approfondie'!D28 -> Défavorable | E35: ='Analyse Approfondie'!E28 -> 2320000 | F35: ='Analyse Approfondie'!F28 -> -0.031120332 | G35: CAPEX > plan
B36: ='Analyse Approfondie'!B29 -> Écart Charges financières | C36: ='Analyse Approfondie'!C29 -> -30000 | D36: ='Analyse Approfondie'!D29 -> Défavorable | E36: ='Analyse Approfondie'!E29 -> 2290000 | F36: ='Analyse Approfondie'!F29 -> -0.0062240664 | G36: Renégociation emprunts
B37: ='Analyse Approfondie'!B30 -> Écart Impôts | C37: ='Analyse Approfondie'!C30 -> 40000 | D37: ='Analyse Approfondie'!D30 -> Favorable | E37: ='Analyse Approfondie'!E30 -> 2330000 | F37: ='Analyse Approfondie'!F30 -> 0.0082987552 | G37: Optimisation fiscale
B39: Note : Graphique Waterfall disponible dans l'onglet Analyse Approfondie (section 5B)
B41: ="⚠️ CONFIDENTIEL — Document de direction généré automatiquement | "&'Données Brutes'!L1&" | Exercice 2025" -> ⚠️ CONFIDENTIEL — Document de direction généré automatiquement | Acier Côte Ouest SAS | Exercice 2025
B42: Liens: Dashboard Interactif | Valorisation DCF | Analyse Approfondie | Benchmark & Alertes

Sheet Accueil
B2: 📊 ANALYSE FINANCIÈRE & CONTRÔLE DE GESTION
B3: ='Données Brutes'!L1&" — Exercices 2023 · 2024 · 2025" -> Acier Côte Ouest SAS — Exercices 2023 · 2024 · 2025
B5: 📌 SOMMAIRE — Naviguez vers chaque onglet
B7: 1 — 📋 Données Brutes | C7: Bilan · CPC · Flux de trésorerie · Budget vs Réel (2023-2025)
B9: 2 — 📐 Ratios & Indicateurs | C9: 30+ ratios : Liquidité, Solvabilité, Rentabilité, Efficacité, Point mort
B11: 3 — 🔍 Analyse Approfondie | C11: 3 Scénarios · Waterfall budget-réel · Prévision trésorerie 12 mois
B13: 4 — 📊 Dashboard Interactif | C13: KPIs, Score /100, Feux tricolores, Graphiques, Radar, Point mort
B15: 5 — 🎯 Benchmark & Alertes | C15: Benchmark sectoriel · 10 alertes automatiques · Scoring
B17: 6 — 📖 Méthodologie | C17: Formules détaillées · Glossaire · Normes · Sources
B21: ✅ 7 onglets · 4 tableaux · 30+ ratios · 3 scénarios · 12 mois trésorerie · 10 alertes · Dashboard graphiques
B23: ="📅 Créé le : Sat Feb 28 2026 | Exercices : 2023-2025 | Devise : EUR (€) | Affichage : "&Accueil!F26 -> 📅 Créé le : Sat Feb 28 2026 | Exercices : 2023-2025 | Devise : EUR (€) | Affichage : M€ (millions)
B25: SANTÉ FINANCIÈRE EN TEMPS RÉEL | E25: ⚙️ PARAMÈTRES D'AFFICHAGE
B26: Score Global /100 : | C26: ='Ratios & Indicateurs'!F90 -> 121 | E26: Unité d'affichage : | F26: M€ (millions)
B27: Feu Tricolore : | C27: ='Ratios & Indicateurs'!F91 -> 🟢 VERT — Bonne santé financière | E27: Diviseur : | F27: =IF(F26="€ (unités)",1,IF(F26="k€ (milliers)",1000,IF(F26="M€ (millions)",1000000,IF(F26="Mrd€ (milliards)",1000000000,1)))) -> 1000000
B28: Altman Z-Score : | C28: ='Ratios & Indicateurs'!F20 -> 2.9382453 | E28: Suffixe : | F28: =IF(F26="€ (unités)","€",IF(F26="k€ (milliers)","k€",IF(F26="M€ (millions)","M€",IF(F26="Mrd€ (milliards)","Mrd€","€")))) -> M€
B29: Marge EBITDA 2025 : | C29: ='Ratios & Indicateurs'!F24 -> 0.14722222 | E29: Décimales : | F29: =IF(F26="€ (unités)",0,IF(F26="k€ (milliers)",0,IF(F26="M€ (millions)",1,IF(F26="Mrd€ (milliards)",2,0)))) -> 1
B30: ROE 2025 : | C30: ='Ratios & Indicateurs'!F27 -> 0.1597432 | E30: Format auto : | F30: ="Montants affichés en "&F28 -> Montants affichés en M€

Sheet Données Brutes
A1: Poste | B1: Catégorie | C1: 2022 | D1: 2023 | E1: 2024 | F1: 2025 | G1: Var. 23→24 | H1: Var. 24→25 | I1: ✔ Contrôle | J1: 🏢 NOM DE L'ENTREPRISE | K1: → | L1: Acier Côte Ouest SAS | M1: Colonne1
A2: Immobilisations incorporelles | B2: Actif Non Courant | C2: 840000 | D2: 610000 | E2: 380000 | F2: 610000 | G2: =IFERROR((E2-D2)/ABS(D2),0) -> -0.37704918 | H2: =IFERROR((F2-E2)/ABS(E2),0) -> 0.60526316 | I2: =IF(ABS(F2-STOCKS!J26)<1,"✅ Stock cohérent","ℹ️ Module STOCKS: "&TEXT(STOCKS!J26,"#,##0")&"€ (périmètre partiel)") -> ℹ️ Module STOCKS: 59520,0€ (périmètre partiel) | J2: =IF(ABS(F2-PLAN_AMORT!O19)<1,"✅ VNC cohérent","ℹ️ Plan amort VNC: "&TEXT(PLAN_AMORT!O19,"#,##0")&"€ / Bilan: "&TEXT(F2,"#,##0")&"€") -> ℹ️ Plan amort VNC: ,0€ / Bilan: 610000,0€ | L2: ⬆ Modifier cette cellule pour mettre à jour tout le classeur
A3: Immobilisations corporelles | B3: Actif Non Courant | C3: 13600000 | D3: 11400000 | E3: 9200000 | F3: 11400000 | G3: =IFERROR((E3-D3)/ABS(D3),0) -> -0.19298246 | H3: =IFERROR((F3-E3)/ABS(E3),0) -> 0.23913043 | I3: =IF(ABS(F3-STOCKS!J27)<1,"✅ Stock cohérent","ℹ️ Module STOCKS: "&TEXT(STOCKS!J27,"#,##0")&"€ (périmètre partiel)") -> ℹ️ Module STOCKS: 236229,892€ (périmètre partiel) | J3: =IF(ABS(F3-PLAN_AMORT!O20)<1,"✅ VNC cohérent","ℹ️ Plan amort VNC: "&TEXT(PLAN_AMORT!O20,"#,##0")&"€ / Bilan: "&TEXT(F3,"#,##0")&"€") -> ℹ️ Plan amort VNC: 1460965,570€ / Bilan: 11400000,0€
A4: Immobilisations financières | B4: Actif Non Courant | C4: 350000 | D4: 350000 | E4: 350000 | F4: 350000 | G4: =IFERROR((E4-D4)/ABS(D4),0) -> 0 | H4: =IFERROR((F4-E4)/ABS(E4),0) -> 0 | I4: =IF(ABS(F4-STOCKS!J28)<1,"✅ Stock cohérent","ℹ️ Module STOCKS: "&TEXT(STOCKS!J28,"#,##0")&"€ (périmètre partiel)") -> ℹ️ Module STOCKS: 121684,887€ (périmètre partiel) | J4: =IF(ABS(F4-PLAN_AMORT!O21)<1,"✅ VNC cohérent","ℹ️ Plan amort VNC: "&TEXT(PLAN_AMORT!O21,"#,##0")&"€ / Bilan: "&TEXT(F4,"#,##0")&"€") -> ℹ️ Plan amort VNC: ,0€ / Bilan: 350000,0€
A5: Stocks matières premières | B5: Actif Courant | C5: 2500000 | D5: 2800000 | E5: 3100000 | F5: 3400000 | G5: =IFERROR((E5-D5)/ABS(D5),0) -> 0.10714286 | H5: =IFERROR((F5-E5)/ABS(E5),0) -> 0.096774194 | I5: =IF(ABS(F5-STOCKS!J29)<1,"✅ Stock cohérent","ℹ️ Module STOCKS: "&TEXT(STOCKS!J29,"#,##0")&"€ (périmètre partiel)") -> ℹ️ Module STOCKS: 5600000,0€ (périmètre partiel) | J5: =IF(ABS(F5-PLAN_AMORT!O22)<1,"✅ VNC cohérent","ℹ️ Plan amort VNC: "&TEXT(PLAN_AMORT!O22,"#,##0")&"€ / Bilan: "&TEXT(F5,"#,##0")&"€") -> ℹ️ Plan amort VNC: ,0€ / Bilan: 3400000,0€
A6: Stocks produits finis | B6: Actif Courant | C6: 1350000 | D6: 1200000 | E6: 1050000 | F6: 1350000 | G6: =IFERROR((E6-D6)/ABS(D6),0) -> -0.125 | H6: =IFERROR((F6-E6)/ABS(E6),0) -> 0.28571429 | I6: =IF(ABS(F6-STOCKS!J30)<1,"✅ Stock cohérent","ℹ️ Module STOCKS: "&TEXT(STOCKS!J30,"#,##0")&"€ (périmètre partiel)") -> ℹ️ Module STOCKS: ,0€ (périmètre partiel) | J6: =IF(ABS(F6-PLAN_AMORT!O23)<1,"✅ VNC cohérent","ℹ️ Plan amort VNC: "&TEXT(PLAN_AMORT!O23,"#,##0")&"€ / Bilan: "&TEXT(F6,"#,##0")&"€") -> ℹ️ Plan amort VNC: ,0€ / Bilan: 1350000,0€
A7: Stocks en-cours de production | B7: Actif Courant | C7: 460000 | D7: 420000 | E7: 380000 | F7: 460000 | G7: =IFERROR((E7-D7)/ABS(D7),0) -> -0.095238095 | H7: =IFERROR((F7-E7)/ABS(E7),0) -> 0.21052632 | I7: =IF(ABS(F7-STOCKS!J31)<1,"✅ Stock cohérent","ℹ️ Module STOCKS: "&TEXT(STOCKS!J31,"#,##0")&"€ (périmètre partiel)") -> ℹ️ Module STOCKS: ,0€ (périmètre partiel) | J7: =IF(ABS(F7-PLAN_AMORT!O24)<1,"✅ VNC cohérent","ℹ️ Plan amort VNC: "&TEXT(PLAN_AMORT!O24,"#,##0")&"€ / Bilan: "&TEXT(F7,"#,##0")&"€") -> ℹ️ Plan amort VNC: ,0€ / Bilan: 460000,0€
A8: Stocks marchandises | B8: Actif Courant | C8: 390000 | D8: 350000 | E8: 310000 | F8: 390000 | G8: =IFERROR((E8-D8)/ABS(D8),0) -> -0.11428571 | H8: =IFERROR((F8-E8)/ABS(E8),0) -> 0.25806452 | I8: =IF(ABS(F8-STOCKS!J32)<1,"✅ Stock cohérent","ℹ️ Module STOCKS: "&TEXT(STOCKS!J32,"#,##0")&"€ (périmètre partiel)") -> ℹ️ Module STOCKS: ,0€ (périmètre partiel) | J8: =IF(ABS(F8-PLAN_AMORT!O25)<1,"✅ VNC cohérent","ℹ️ Plan amort VNC: "&TEXT(PLAN_AMORT!O25,"#,##0")&"€ / Bilan: "&TEXT(F8,"#,##0")&"€") -> ℹ️ Plan amort VNC: ,0€ / Bilan: 390000,0€
A9: Créances clients | B9: Actif Courant | C9: 3800000 | D9: 4200000 | E9: 4600000 | F9: 5100000 | G9: =IFERROR((E9-D9)/ABS(D9),0) -> 0.095238095 | H9: =IFERROR((F9-E9)/ABS(E9),0) -> 0.10869565 | I9: =IF(ABS(F9-STOCKS!J33)<1,"✅ Stock cohérent","ℹ️ Module STOCKS: "&TEXT(STOCKS!J33,"#,##0")&"€ (périmètre partiel)") -> ℹ️ Module STOCKS: ,0€ (périmètre partiel) | J9: =IF(ABS(F9-PLAN_AMORT!O26)<1,"✅ VNC cohérent","ℹ️ Plan amort VNC: "&TEXT(PLAN_AMORT!O26,"#,##0")&"€ / Bilan: "&TEXT(F9,"#,##0")&"€") -> ℹ️ Plan amort VNC: ,0€ / Bilan: 5100000,0€
A10: Autres créances | B10: Actif Courant | C10: 340000 | D10: 380000 | E10: 420000 | F10: 460000 | G10: =IFERROR((E10-D10)/ABS(D10),0) -> 0.10526316 | H10: =IFERROR((F10-E10)/ABS(E10),0) -> 0.095238095 | I10: =IF(ABS(F10-STOCKS!J34)<1,"✅ Stock cohérent","ℹ️ Module STOCKS: "&TEXT(STOCKS!J34,"#,##0")&"€ (périmètre partiel)") -> ℹ️ Module STOCKS: ,0€ (périmètre partiel) | J10: =IF(ABS(F10-PLAN_AMORT!O27)<1,"✅ VNC cohérent","ℹ️ Plan amort VNC: "&TEXT(PLAN_AMORT!O27,"#,##0")&"€ / Bilan: "&TEXT(F10,"#,##0")&"€") -> ℹ️ Plan amort VNC: ,0€ / Bilan: 460000,0€
A11: Trésorerie active | B11: Actif Courant | C11: 1350000 | D11: 1100000 | E11: 850000 | F11: 1650000 | G11: =IFERROR((E11-D11)/ABS(D11),0) -> -0.22727273 | H11: =IFERROR((F11-E11)/ABS(E11),0) -> 0.94117647 | I11: =IF(ABS(F11-STOCKS!J35)<1,"✅ Stock cohérent","ℹ️ Module STOCKS: "&TEXT(STOCKS!J35,"#,##0")&"€ (périmètre partiel)") -> ℹ️ Module STOCKS: ,0€ (périmètre partiel) | J11: =IF(ABS(F11-PLAN_AMORT!O28)<1,"✅ VNC cohérent","ℹ️ Plan amort VNC: "&TEXT(PLAN_AMORT!O28,"#,##0")&"€ / Bilan: "&TEXT(F11,"#,##0")&"€") -> ℹ️ Plan amort VNC: ,0€ / Bilan: 1650000,0€
A12: VMP | B12: Actif Courant | C12: 250000 | D12: 200000 | E12: 150000 | F12: 300000 | G12: =IFERROR((E12-D12)/ABS(D12),0) -> -0.25 | H12: =IFERROR((F12-E12)/ABS(E12),0) -> 1 | I12: =IF(ABS(F12-STOCKS!J36)<1,"✅ Stock cohérent","ℹ️ Module STOCKS: "&TEXT(STOCKS!J36,"#,##0")&"€ (périmètre partiel)") -> ℹ️ Module STOCKS: ,0€ (périmètre partiel) | J12: =IF(ABS(F12-PLAN_AMORT!O29)<1,"✅ VNC cohérent","ℹ️ Plan amort VNC: "&TEXT(PLAN_AMORT!O29,"#,##0")&"€ / Bilan: "&TEXT(F12,"#,##0")&"€") -> ℹ️ Plan amort VNC: ,0€ / Bilan: 300000,0€
A13: Charges constatées d'avance | B13: Actif Courant | C13: 100000 | D13: 120000 | E13: 140000 | F13: 150000 | G13: =IFERROR((E13-D13)/ABS(D13),0) -> 0.16666667 | H13: =IFERROR((F13-E13)/ABS(E13),0) -> 0.071428571 | I13: =IF(ABS(F13-STOCKS!J37)<1,"✅ Stock cohérent","ℹ️ Module STOCKS: "&TEXT(STOCKS!J37,"#,##0")&"€ (périmètre partiel)") -> ℹ️ Module STOCKS: ,0€ (périmètre partiel) | J13: =IF(ABS(F13-PLAN_AMORT!O30)<1,"✅ VNC cohérent","ℹ️ Plan amort VNC: "&TEXT(PLAN_AMORT!O30,"#,##0")&"€ / Bilan: "&TEXT(F13,"#,##0")&"€") -> ℹ️ Plan amort VNC: ,0€ / Bilan: 150000,0€
A14: Capital social | B14: Capitaux Propres | C14: 2000000 | D14: 2000000 | E14: 2000000 | F14: 2000000 | G14: =IFERROR((E14-D14)/ABS(D14),0) -> 0 | H14: =IFERROR((F14-E14)/ABS(E14),0) -> 0 | I14: =IF(ABS(F14-STOCKS!J38)<1,"✅ Stock cohérent","ℹ️ Module STOCKS: "&TEXT(STOCKS!J38,"#,##0")&"€ (périmètre partiel)") -> ℹ️ Module STOCKS: ,0€ (périmètre partiel) | J14: =IF(ABS(F14-PLAN_AMORT!O31)<1,"✅ VNC cohérent","ℹ️ Plan amort VNC: "&TEXT(PLAN_AMORT!O31,"#,##0")&"€ / Bilan: "&TEXT(F14,"#,##0")&"€") -> ℹ️ Plan amort VNC: ,0€ / Bilan: 2000000,0€
A15: Réserves | B15: Capitaux Propres | C15: 3300000 | D15: 4200000 | E15: 5100000 | F15: 6400000 | G15: =IFERROR((E15-D15)/ABS(D15),0) -> 0.21428571 | H15: =IFERROR((F15-E15)/ABS(E15),0) -> 0.25490196 | I15: =IF(ABS(F15-STOCKS!J39)<1,"✅ Stock cohérent","ℹ️ Module STOCKS: "&TEXT(STOCKS!J39,"#,##0")&"€ (périmètre partiel)") -> ℹ️ Module STOCKS: ,0€ (périmètre partiel) | J15: =IF(ABS(F15-PLAN_AMORT!O32)<1,"✅ VNC cohérent","ℹ️ Plan amort VNC: "&TEXT(PLAN_AMORT!O32,"#,##0")&"€ / Bilan: "&TEXT(F15,"#,##0")&"€") -> ℹ️ Plan amort VNC: ,0€ / Bilan: 6400000,0€
A16: Report à nouveau | B16: Capitaux Propres | C16: 6340000 | D16: =(D2+D3+D4+D5+D6+D7+D8+D9+D10+D11+D12+D13)-(D14+D15+D17+D18+D19+D20+D21+D22+D23+D24+D25+D26) -> 3505000 | E16: =D29-(E14+E15+E17+E18+E19+E20+E21+E22+E23+E24+E25+E26) -> 675000 | F16: =E29-(F14+F15+F17+F18+F19+F20+F21+F22+F23+F24+F25+F26) -> 2475000 | G16: =IFERROR((E16-D16)/ABS(D16),0) -> -0.80741797 | H16: =IFERROR((F16-E16)/ABS(E16),0) -> 2.6666667 | I16: =IF(ABS(F16-STOCKS!J40)<1,"✅ Stock cohérent","ℹ️ Module STOCKS: "&TEXT(STOCKS!J40,"#,##0")&"€ (périmètre partiel)") -> ℹ️ Module STOCKS: ,0€ (périmètre partiel) | J16: =IF(ABS(F16-PLAN_AMORT!O33)<1,"✅ VNC cohérent","ℹ️ Plan amort VNC: "&TEXT(PLAN_AMORT!O33,"#,##0")&"€ / Bilan: "&TEXT(F16,"#,##0")&"€") -> ℹ️ Plan amort VNC: ,0€ / Bilan: 2475000,0€
A17: Résultat net | B17: Capitaux Propres | C17: 1900000 | D17: =(D38+D39+D40+D41+D42+D51+D53)-(D43+D44+D45+D46+D47+D48+D49+D50+D52+D54+D55+D56) -> 1975000 | E17: =(E38+E39+E40+E41+E42+E51+E53)-(E43+E44+E45+E46+E47+E48+E49+E50+E52+E54+E55+E56) -> 2045000 | F17: =(F38+F39+F40+F41+F42+F51+F53)-(F43+F44+F45+F46+F47+F48+F49+F50+F52+F54+F55+F56) -> 2115000 | G17: =IFERROR((E17-D17)/ABS(D17),0) -> 0.035443038 | H17: =IFERROR((F17-E17)/ABS(E17),0) -> 0.034229829 | I17: =IF(ABS(F17-STOCKS!J41)<1,"✅ Stock cohérent","ℹ️ Module STOCKS: "&TEXT(STOCKS!J41,"#,##0")&"€ (périmètre partiel)") -> ℹ️ Module STOCKS: ,0€ (périmètre partiel) | J17: =IF(ABS(F17-PLAN_AMORT!O34)<1,"✅ VNC cohérent","ℹ️ Plan amort VNC: "&TEXT(PLAN_AMORT!O34,"#,##0")&"€ / Bilan: "&TEXT(F17,"#,##0")&"€") -> ℹ️ Plan amort VNC: ,0€ / Bilan: 2115000,0€
A18: Provisions réglementées | B18: Capitaux Propres | C18: 100000 | D18: 150000 | E18: 200000 | F18: 250000 | G18: =IFERROR((E18-D18)/ABS(D18),0) -> 0.33333333 | H18: =IFERROR((F18-E18)/ABS(E18),0) -> 0.25 | I18: =IF(ABS(F18-STOCKS!J42)<1,"✅ Stock cohérent","ℹ️ Module STOCKS: "&TEXT(STOCKS!J42,"#,##0")&"€ (périmètre partiel)") -> ℹ️ Module STOCKS: ,0€ (périmètre partiel) | J18: =IF(ABS(F18-PLAN_AMORT!O35)<1,"✅ VNC cohérent","ℹ️ Plan amort VNC: "&TEXT(PLAN_AMORT!O35,"#,##0")&"€ / Bilan: "&TEXT(F18,"#,##0")&"€") -> ℹ️ Plan amort VNC: ,0€ / Bilan: 250000,0€
A19: Emprunts obligataires | B19: Dettes Non Courantes | C19: 1800000 | D19: 1500000 | E19: 1200000 | F19: 900000 | G19: =IFERROR((E19-D19)/ABS(D19),0) -> -0.2 | H19: =IFERROR((F19-E19)/ABS(E19),0) -> -0.25 | I19: =IF(ABS(F19-STOCKS!J43)<1,"✅ Stock cohérent","ℹ️ Module STOCKS: "&TEXT(STOCKS!J43,"#,##0")&"€ (périmètre partiel)") -> ℹ️ Module STOCKS: ,0€ (périmètre partiel) | J19: =IF(ABS(F19-PLAN_AMORT!O36)<1,"✅ VNC cohérent","ℹ️ Plan amort VNC: "&TEXT(PLAN_AMORT!O36,"#,##0")&"€ / Bilan: "&TEXT(F19,"#,##0")&"€") -> ℹ️ Plan amort VNC: ,0€ / Bilan: 900000,0€
A20: Emprunts bancaires LT | B20: Dettes Non Courantes | C20: 4200000 | D20: 3800000 | E20: 3400000 | F20: 4800000 | G20: =IFERROR((E20-D20)/ABS(D20),0) -> -0.10526316 | H20: =IFERROR((F20-E20)/ABS(E20),0) -> 0.41176471 | I20: =IF(ABS(F20-STOCKS!J44)<1,"✅ Stock cohérent","ℹ️ Module STOCKS: "&TEXT(STOCKS!J44,"#,##0")&"€ (périmètre partiel)") -> ℹ️ Module STOCKS: ,0€ (périmètre partiel) | J20: =IF(ABS(F20-PLAN_AMORT!O37)<1,"✅ VNC cohérent","ℹ️ Plan amort VNC: "&TEXT(PLAN_AMORT!O37,"#,##0")&"€ / Bilan: "&TEXT(F20,"#,##0")&"€") -> ℹ️ Plan amort VNC: ,0€ / Bilan: 4800000,0€
A21: Provisions risques | B21: Dettes Non Courantes | C21: 250000 | D21: 280000 | E21: 310000 | F21: 340000 | G21: =IFERROR((E21-D21)/ABS(D21),0) -> 0.10714286 | H21: =IFERROR((F21-E21)/ABS(E21),0) -> 0.096774194 | I21: =IF(ABS(F21-STOCKS!J45)<1,"✅ Stock cohérent","ℹ️ Module STOCKS: "&TEXT(STOCKS!J45,"#,##0")&"€ (périmètre partiel)") -> ℹ️ Module STOCKS: ,0€ (périmètre partiel) | J21: =IF(ABS(F21-PLAN_AMORT!O38)<1,"✅ VNC cohérent","ℹ️ Plan amort VNC: "&TEXT(PLAN_AMORT!O38,"#,##0")&"€ / Bilan: "&TEXT(F21,"#,##0")&"€") -> ℹ️ Plan amort VNC: ,0€ / Bilan: 340000,0€
A22: Dettes fournisseurs | B22: Dettes Courantes | C22: 2800000 | D22: 3100000 | E22: 3400000 | F22: 3750000 | G22: =IFERROR((E22-D22)/ABS(D22),0) -> 0.096774194 | H22: =IFERROR((F22-E22)/ABS(E22),0) -> 0.10294118 | I22: =IF(ABS(F22-STOCKS!J46)<1,"✅ Stock cohérent","ℹ️ Module STOCKS: "&TEXT(STOCKS!J46,"#,##0")&"€ (périmètre partiel)") -> ℹ️ Module STOCKS: ,0€ (périmètre partiel) | J22: =IF(ABS(F22-PLAN_AMORT!O39)<1,"✅ VNC cohérent","ℹ️ Plan amort VNC: "&TEXT(PLAN_AMORT!O39,"#,##0")&"€ / Bilan: "&TEXT(F22,"#,##0")&"€") -> ℹ️ Plan amort VNC: ,0€ / Bilan: 3750000,0€
A23: Dettes fiscales & sociales | B23: Dettes Courantes | C23: 1320000 | D23: 1450000 | E23: 1580000 | F23: 1720000 | G23: =IFERROR((E23-D23)/ABS(D23),0) -> 0.089655172 | H23: =IFERROR((F23-E23)/ABS(E23),0) -> 0.088607595 | I23: =IF(ABS(F23-STOCKS!J47)<1,"✅ Stock cohérent","ℹ️ Module STOCKS: "&TEXT(STOCKS!J47,"#,##0")&"€ (périmètre partiel)") -> ℹ️ Module STOCKS: ,0€ (périmètre partiel) | J23: =IF(ABS(F23-PLAN_AMORT!O40)<1,"✅ VNC cohérent","ℹ️ Plan amort VNC: "&TEXT(PLAN_AMORT!O40,"#,##0")&"€ / Bilan: "&TEXT(F23,"#,##0")&"€") -> ℹ️ Plan amort VNC: ,0€ / Bilan: 1720000,0€
A24: Concours bancaires courants | B24: Dettes Courantes | C24: 1000000 | D24: 800000 | E24: 600000 | F24: 400000 | G24: =IFERROR((E24-D24)/ABS(D24),0) -> -0.25 | H24: =IFERROR((F24-E24)/ABS(E24),0) -> -0.33333333 | I24: =IF(ABS(F24-STOCKS!J48)<1,"✅ Stock cohérent","ℹ️ Module STOCKS: "&TEXT(STOCKS!J48,"#,##0")&"€ (périmètre partiel)") -> ℹ️ Module STOCKS: ,0€ (périmètre partiel) | J24: =IF(ABS(F24-PLAN_AMORT!O41)<1,"✅ VNC cohérent","ℹ️ Plan amort VNC: "&TEXT(PLAN_AMORT!O41,"#,##0")&"€ / Bilan: "&TEXT(F24,"#,##0")&"€") -> ℹ️ Plan amort VNC: ,0€ / Bilan: 400000,0€
A25: Autres dettes courantes | B25: Dettes Courantes | C25: 260000 | D25: 290000 | E25: 320000 | F25: 350000 | G25: =IFERROR((E25-D25)/ABS(D25),0) -> 0.10344828 | H25: =IFERROR((F25-E25)/ABS(E25),0) -> 0.09375 | I25: =IF(ABS(F25-STOCKS!J49)<1,"✅ Stock cohérent","ℹ️ Module STOCKS: "&TEXT(STOCKS!J49,"#,##0")&"€ (périmètre partiel)") -> ℹ️ Module STOCKS: ,0€ (périmètre partiel) | J25: =IF(ABS(F25-PLAN_AMORT!O42)<1,"✅ VNC cohérent","ℹ️ Plan amort VNC: "&TEXT(PLAN_AMORT!O42,"#,##0")&"€ / Bilan: "&TEXT(F25,"#,##0")&"€") -> ℹ️ Plan amort VNC: ,0€ / Bilan: 350000,0€
A26: Produits constatés d'avance | B26: Dettes Courantes | C26: 60000 | D26: 80000 | E26: 100000 | F26: 120000 | G26: =IFERROR((E26-D26)/ABS(D26),0) -> 0.25 | H26: =IFERROR((F26-E26)/ABS(E26),0) -> 0.2 | I26: =IF(ABS(F26-STOCKS!J50)<1,"✅ Stock cohérent","ℹ️ Module STOCKS: "&TEXT(STOCKS!J50,"#,##0")&"€ (périmètre partiel)") -> ℹ️ Module STOCKS: ,0€ (périmètre partiel) | J26: =IF(ABS(F26-PLAN_AMORT!O43)<1,"✅ VNC cohérent","ℹ️ Plan amort VNC: "&TEXT(PLAN_AMORT!O43,"#,##0")&"€ / Bilan: "&TEXT(F26,"#,##0")&"€") -> ℹ️ Plan amort VNC: ,0€ / Bilan: 120000,0€
A28: ✔ CONTRÔLE BILAN
A29: Total Actif (2025) | C29: =SUMIF(B2:B26,"Actif Non Courant",C2:C26)+SUMIF(B2:B26,"Actif Courant",C2:C26) -> 25330000 | D29: =SUMIF(B2:B26,"Actif Non Courant",E2:E26)+SUMIF(B2:B26,"Actif Courant",E2:E26) -> 20930000 | E29: =SUMIF(B2:B26,"Actif Non Courant",F2:F26)+SUMIF(B2:B26,"Actif Courant",F2:F26) -> 25620000
A30: Total Passif (CP+Dettes) | C30: =SUMIF(B2:B26,"Capitaux Propres",C2:C26)+SUMIF(B2:B26,"Dettes Non Courantes",C2:C26)+SUMIF(B2:B26,"Dettes Courantes",C2:C26) -> 25330000 | D30: =SUMIF(B2:B26,"Capitaux Propres",E2:E26)+SUMIF(B2:B26,"Dettes Non Courantes",E2:E26)+SUMIF(B2:B26,"Dettes Courantes",E2:E26) -> 20930000 | E30: =SUMIF(B2:B26,"Capitaux Propres",F2:F26)+SUMIF(B2:B26,"Dettes Non Courantes",F2:F26)+SUMIF(B2:B26,"Dettes Courantes",F2:F26) -> 25620000
A31: ⚖️ Écart (= 0 si équilibré) | C31: =C29-C30 -> 0 | D31: =D29-D30 -> 0 | E31: =E29-E30 -> 0
A33: ✔ CONTRÔLE CPC
A34: RN calculé (Produits − Charges) | C34: =(D38+D39+D40+D41+D42+D51+D53)-(D43+D44+D45+D46+D47+D48+D49+D50+D52+D54+D55+D56) -> 1975000 | D34: =(E38+E39+E40+E41+E42+E51+E53)-(E43+E44+E45+E46+E47+E48+E49+E50+E52+E54+E55+E56) -> 2045000 | E34: =(F38+F39+F40+F41+F42+F51+F53)-(F43+F44+F45+F46+F47+F48+F49+F50+F52+F54+F55+F56) -> 2115000
A35: ⚖️ Écart vs Bilan (= 0 si cohérent) | C35: =C34-D17 -> 0 | D35: =D34-E17 -> 0 | E35: =E34-F17 -> 0
A36: T_CPC — Compte de Résultat
A37: Poste | B37: Section | C37: 2022 | D37: 2023 | E37: 2024 | F37: 2025 | G37: Var. 23→24 | H37: Var. 24→25 | I37: Var. 24→26 | J37: Var. 24→27
A38: Chiffre d'affaires net | B38: Produits Exploitation | C38: 27200000 | D38: 28500000 | E38: 29800000 | F38: 32400000 | G38: =IFERROR((E38-D38)/ABS(D38),0) -> 0.045614035 | H38: =IFERROR((F38-E38)/ABS(E38),0) -> 0.087248322 | I38: 🔗 Contrôles modules | J38: =IF(ABS(F38-ECARTS_BU!AB10)<1,"✅ CA cohérent","ℹ️ Écarts_BU CA consol: "&TEXT(ECARTS_BU!AB10,"#,##0")&"€ (5 BU) vs CPC: "&TEXT(F38,"#,##0")&"€") -> ℹ️ Écarts_BU CA consol: 13100000,0€ (5 BU) vs CPC: 32400000,0€
A39: Production stockée | B39: Produits Exploitation | C39: 260000 | D39: 220000 | E39: 180000 | F39: 250000 | G39: =IFERROR((E39-D39)/ABS(D39),0) -> -0.18181818 | H39: =IFERROR((F39-E39)/ABS(E39),0) -> 0.38888889 | J39: =IF(ABS(F39-ECARTS_BU!AB11)<1,"✅ CA cohérent","ℹ️ Écarts_BU CA consol: "&TEXT(ECARTS_BU!AB11,"#,##0")&"€ (5 BU) vs CPC: "&TEXT(F39,"#,##0")&"€") -> ℹ️ Écarts_BU CA consol: 35800,0€ (5 BU) vs CPC: 250000,0€
A40: Production immobilisée | B40: Produits Exploitation | C40: 60000 | D40: 80000 | E40: 95000 | F40: 110000 | G40: =IFERROR((E40-D40)/ABS(D40),0) -> 0.1875 | H40: =IFERROR((F40-E40)/ABS(E40),0) -> 0.15789474 | J40: =IF(ABS(F40-ECARTS_BU!AB12)<1,"✅ CA cohérent","ℹ️ Écarts_BU CA consol: "&TEXT(ECARTS_BU!AB12,"#,##0")&"€ (5 BU) vs CPC: "&TEXT(F40,"#,##0")&"€") -> ℹ️ Écarts_BU CA consol: 2200,0€ (5 BU) vs CPC: 110000,0€
A41: Subventions exploitation | B41: Produits Exploitation | C41: 140000 | D41: 120000 | E41: 100000 | F41: 90000 | G41: =IFERROR((E41-D41)/ABS(D41),0) -> -0.16666667 | H41: =IFERROR((F41-E41)/ABS(E41),0) -> -0.1 | J41: =IF(ABS(F41-ECARTS_BU!AB13)<1,"✅ CA cohérent","ℹ️ Écarts_BU CA consol: "&TEXT(ECARTS_BU!AB13,"#,##0")&"€ (5 BU) vs CPC: "&TEXT(F41,"#,##0")&"€") -> ℹ️ Écarts_BU CA consol: -3656500,0€ (5 BU) vs CPC: 90000,0€
A42: Autres produits exploitation | B42: Produits Exploitation | C42: 150000 | D42: 180000 | E42: 210000 | F42: 240000 | G42: =IFERROR((E42-D42)/ABS(D42),0) -> 0.16666667 | H42: =IFERROR((F42-E42)/ABS(E42),0) -> 0.14285714 | J42: =IF(ABS(F42-ECARTS_BU!AB14)<1,"✅ CA cohérent","ℹ️ Écarts_BU CA consol: "&TEXT(ECARTS_BU!AB14,"#,##0")&"€ (5 BU) vs CPC: "&TEXT(F42,"#,##0")&"€") -> ℹ️ Écarts_BU CA consol: -2379720,0€ (5 BU) vs CPC: 240000,0€
...

Sheet Ratios & Indicateurs
B1: TABLEAU DE BORD DES RATIOS FINANCIERS
B2: ='Données Brutes'!L1&" · Exercices 2023 — 2024 — 2025 · Calculs automatiques depuis onglet Données Brutes" -> Acier Côte Ouest SAS · Exercices 2023 — 2024 — 2025 · Calculs automatiques depuis onglet Données Brutes
B4: Nº | C4: Indicateur | D4: 2023 | E4: 2024 | F4: 2025 | G4: Norme | H4: Var. 24→25 | I4: Statut
B5: 💧 LIQUIDITÉ & TRÉSORERIE
B6: 1 | C6: Liquidité Générale (Current Ratio) | D6: =IFERROR(SUMIF('Données Brutes'!B2:B26,"Actif Courant",'Données Brutes'!D2:D26)/SUMIF('Données Brutes'!B2:B26,"Dettes Courantes",'Données Brutes'!D2:D26),0) -> 1.8828671 | E6: =IFERROR(SUMIF('Données Brutes'!B2:B26,"Actif Courant",'Données Brutes'!E2:E26)/SUMIF('Données Brutes'!B2:B26,"Dettes Courantes",'Données Brutes'!E2:E26),0) -> 1.8333333 | F6: =IFERROR(SUMIF('Données Brutes'!B2:B26,"Actif Courant",'Données Brutes'!F2:F26)/SUMIF('Données Brutes'!B2:B26,"Dettes Courantes",'Données Brutes'!F2:F26),0) -> 2.0914826 | G6: > 1,5 | H6: =IFERROR((F6-E6)/ABS(E6),0) -> 0.14080872 | I6: =IF(F6>=1.5,"✅ Conforme",IF(F6>=1,"⚠️ Attention","🔴 Critique")) -> ✅ Conforme
B7: 2 | C7: Liquidité Réduite — Quick Ratio | D7: =IFERROR((SUMIF('Données Brutes'!B2:B26,"Actif Courant",'Données Brutes'!D2:D26)-(SUMIF('Données Brutes'!A2:A26,"Stocks matières premières",'Données Brutes'!D2:D26)+SUMIF('Données Brutes'!A2:A26,"Stocks produits finis",'Données Brutes'!D2:D26)+SUMIF('Données Brutes'!A2:A26,"Stocks en-cours de production",'Données Brutes'!D2:D26)+SUMIF('Données Brutes'!A2:A26,"Stocks marchandises",'Données Brutes'!D2:D26)))/SUMIF('Données Brutes'!B2:B26,"Dettes Courantes",'Données Brutes'!D2:D26),0) -> 1.048951 | E7: =IFERROR((SUMIF('Données Brutes'!B2:B26,"Actif Courant",'Données Brutes'!E2:E26)-(SUMIF('Données Brutes'!A2:A26,"Stocks matières premières",'Données Brutes'!E2:E26)+SUMIF('Données Brutes'!A2:A26,"Stocks produits finis",'Données Brutes'!E2:E26)+SUMIF('Données Brutes'!A2:A26,"Stocks en-cours de production",'Données Brutes'!E2:E26)+SUMIF('Données Brutes'!A2:A26,"Stocks marchandises",'Données Brutes'!E2:E26)))/SUMIF('Données Brutes'!B2:B26,"Dettes Courantes",'Données Brutes'!E2:E26),0) -> 1.0266667 | F7: =IFERROR((SUMIF('Données Brutes'!B2:B26,"Actif Courant",'Données Brutes'!F2:F26)-(SUMIF('Données Brutes'!A2:A26,"Stocks matières premières",'Données Brutes'!F2:F26)+SUMIF('Données Brutes'!A2:A26,"Stocks produits finis",'Données Brutes'!F2:F26)+SUMIF('Données Brutes'!A2:A26,"Stocks en-cours de production",'Données Brutes'!F2:F26)+SUMIF('Données Brutes'!A2:A26,"Stocks marchandises",'Données Brutes'!F2:F26)))/SUMIF('Données Brutes'!B2:B26,"Dettes Courantes",'Données Brutes'!F2:F26),0) -> 1.2082019 | G7: > 1,0 | H7: =IFERROR((F7-E7)/ABS(E7),0) -> 0.17682003 | I7: =IF(F7>=1,"✅ Conforme",IF(F7>=0.7,"⚠️ Attention","🔴 Critique")) -> ✅ Conforme
B8: 3 | C8: Liquidité Immédiate — Cash Ratio | D8: =IFERROR((SUMIF('Données Brutes'!A2:A26,"Trésorerie active",'Données Brutes'!D2:D26)+SUMIF('Données Brutes'!A2:A26,"VMP",'Données Brutes'!D2:D26))/SUMIF('Données Brutes'!B2:B26,"Dettes Courantes",'Données Brutes'!D2:D26),0) -> 0.22727273 | E8: =IFERROR((SUMIF('Données Brutes'!A2:A26,"Trésorerie active",'Données Brutes'!E2:E26)+SUMIF('Données Brutes'!A2:A26,"VMP",'Données Brutes'!E2:E26))/SUMIF('Données Brutes'!B2:B26,"Dettes Courantes",'Données Brutes'!E2:E26),0) -> 0.16666667 | F8: =IFERROR((SUMIF('Données Brutes'!A2:A26,"Trésorerie active",'Données Brutes'!F2:F26)+SUMIF('Données Brutes'!A2:A26,"VMP",'Données Brutes'!F2:F26))/SUMIF('Données Brutes'!B2:B26,"Dettes Courantes",'Données Brutes'!F2:F26),0) -> 0.30757098 | G8: > 0,2 | H8: =IFERROR((F8-E8)/ABS(E8),0) -> 0.84542587 | I8: =IF(F8>=0.3,"✅ Conforme",IF(F8>=0.2,"⚠️ Attention","🔴 Critique")) -> ✅ Conforme
B9: 4 | C9: FRNG — Fonds de Roulement Net Global | D9: =IFERROR(SUMIF('Données Brutes'!B2:B26,"Capitaux Propres",'Données Brutes'!D2:D26)+SUMIF('Données Brutes'!B2:B26,"Dettes Non Courantes",'Données Brutes'!D2:D26)-SUMIF('Données Brutes'!B2:B26,"Actif Non Courant",'Données Brutes'!D2:D26),0) -> 5050000 | E9: =IFERROR(SUMIF('Données Brutes'!B2:B26,"Capitaux Propres",'Données Brutes'!E2:E26)+SUMIF('Données Brutes'!B2:B26,"Dettes Non Courantes",'Données Brutes'!E2:E26)-SUMIF('Données Brutes'!B2:B26,"Actif Non Courant",'Données Brutes'!E2:E26),0) -> 5000000 | F9: =IFERROR(SUMIF('Données Brutes'!B2:B26,"Capitaux Propres",'Données Brutes'!F2:F26)+SUMIF('Données Brutes'!B2:B26,"Dettes Non Courantes",'Données Brutes'!F2:F26)-SUMIF('Données Brutes'!B2:B26,"Actif Non Courant",'Données Brutes'!F2:F26),0) -> 6920000 | G9: > 0 | H9: =IFERROR((F9-E9)/ABS(E9),0) -> 0.384 | I9: =IF(F9>0,"✅ Conforme","🔴 Critique") -> ✅ Conforme
B10: 5 | C10: BFR — Besoin en Fonds de Roulement | D10: =IFERROR((SUMIF('Données Brutes'!A2:A26,"Stocks matières premières",'Données Brutes'!D2:D26)+SUMIF('Données Brutes'!A2:A26,"Stocks produits finis",'Données Brutes'!D2:D26)+SUMIF('Données Brutes'!A2:A26,"Stocks en-cours de production",'Données Brutes'!D2:D26)+SUMIF('Données Brutes'!A2:A26,"Stocks marchandises",'Données Brutes'!D2:D26))+SUMIF('Données Brutes'!A2:A26,"Créances clients",'Données Brutes'!D2:D26)+SUMIF('Données Brutes'!A2:A26,"Autres créances",'Données Brutes'!D2:D26)-SUMIF('Données Brutes'!A2:A26,"Dettes fournisseurs",'Données Brutes'!D2:D26)-SUMIF('Données Brutes'!A2:A26,"Dettes fiscales & sociales",'Données Brutes'!D2:D26)-SUMIF('Données Brutes'!A2:A26,"Autres dettes courantes",'Données Brutes'!D2:D26),0) -> 4510000 | E10: =IFERROR((SUMIF('Données Brutes'!A2:A26,"Stocks matières premières",'Données Brutes'!E2:E26)+SUMIF('Données Brutes'!A2:A26,"Stocks produits finis",'Données Brutes'!E2:E26)+SUMIF('Données Brutes'!A2:A26,"Stocks en-cours de production",'Données Brutes'!E2:E26)+SUMIF('Données Brutes'!A2:A26,"Stocks marchandises",'Données Brutes'!E2:E26))+SUMIF('Données Brutes'!A2:A26,"Créances clients",'Données Brutes'!E2:E26)+SUMIF('Données Brutes'!A2:A26,"Autres créances",'Données Brutes'!E2:E26)-SUMIF('Données Brutes'!A2:A26,"Dettes fournisseurs",'Données Brutes'!E2:E26)-SUMIF('Données Brutes'!A2:A26,"Dettes fiscales & sociales",'Données Brutes'!E2:E26)-SUMIF('Données Brutes'!A2:A26,"Autres dettes courantes",'Données Brutes'!E2:E26),0) -> 4560000 | F10: =IFERROR((SUMIF('Données Brutes'!A2:A26,"Stocks matières premières",'Données Brutes'!F2:F26)+SUMIF('Données Brutes'!A2:A26,"Stocks produits finis",'Données Brutes'!F2:F26)+SUMIF('Données Brutes'!A2:A26,"Stocks en-cours de production",'Données Brutes'!F2:F26)+SUMIF('Données Brutes'!A2:A26,"Stocks marchandises",'Données Brutes'!F2:F26))+SUMIF('Données Brutes'!A2:A26,"Créances clients",'Données Brutes'!F2:F26)+SUMIF('Données Brutes'!A2:A26,"Autres créances",'Données Brutes'!F2:F26)-SUMIF('Données Brutes'!A2:A26,"Dettes fournisseurs",'Données Brutes'!F2:F26)-SUMIF('Données Brutes'!A2:A26,"Dettes fiscales & sociales",'Données Brutes'!F2:F26)-SUMIF('Données Brutes'!A2:A26,"Autres dettes courantes",'Données Brutes'!F2:F26),0) -> 5340000 | G10: Structurel | H10: =IFERROR((F10-E10)/ABS(E10),0) -> 0.17105263 | I10: =IF(F10>0,"✅ Structurel positif","⚠️ BFR négatif") -> ✅ Structurel positif
B11: 05b | C11: BFR en jours de CA | D11: =IFERROR(D10/SUMIF('Données Brutes'!A38:A56,"Chiffre d'affaires net",'Données Brutes'!D38:D56)*365,0) -> 57.759649 | E11: =IFERROR(E10/SUMIF('Données Brutes'!A38:A56,"Chiffre d'affaires net",'Données Brutes'!E38:E56)*365,0) -> 55.852349 | F11: =IFERROR(F10/SUMIF('Données Brutes'!A38:A56,"Chiffre d'affaires net",'Données Brutes'!F38:F56)*365,0) -> 60.157407 | G11: < 60 jours | H11: =IFERROR((F11-E11)/ABS(E11),0) -> 0.077079272 | I11: =IF(F11<45,"✅ Conforme",IF(F11<60,"⚠️ Attention","🔴 Critique")) -> 🔴 Critique
B13: 🏦 SOLVABILITÉ & ENDETTEMENT
B14: 7 | C14: Ratio Endettement — Debt / Equity | D14: =IFERROR(((SUMIF('Données Brutes'!B2:B26,"Actif Non Courant",'Données Brutes'!D2:D26)+SUMIF('Données Brutes'!B2:B26,"Actif Courant",'Données Brutes'!D2:D26))-SUMIF('Données Brutes'!B2:B26,"Capitaux Propres",'Données Brutes'!D2:D26))/SUMIF('Données Brutes'!B2:B26,"Capitaux Propres",'Données Brutes'!D2:D26),0) -> 0.95519865 | E14: =IFERROR(((SUMIF('Données Brutes'!B2:B26,"Actif Non Courant",'Données Brutes'!E2:E26)+SUMIF('Données Brutes'!B2:B26,"Actif Courant",'Données Brutes'!E2:E26))-SUMIF('Données Brutes'!B2:B26,"Capitaux Propres",'Données Brutes'!E2:E26))/SUMIF('Données Brutes'!B2:B26,"Capitaux Propres",'Données Brutes'!E2:E26),0) -> 1.0888224 | F14: =IFERROR(((SUMIF('Données Brutes'!B2:B26,"Actif Non Courant",'Données Brutes'!F2:F26)+SUMIF('Données Brutes'!B2:B26,"Actif Courant",'Données Brutes'!F2:F26))-SUMIF('Données Brutes'!B2:B26,"Capitaux Propres",'Données Brutes'!F2:F26))/SUMIF('Données Brutes'!B2:B26,"Capitaux Propres",'Données Brutes'!F2:F26),0) -> 0.93504532 | G14: < 1,0 | H14: =IFERROR((F14-E14)/ABS(E14),0) -> -0.14123244 | I14: =IF(F14<1,"✅ Conforme",IF(F14<2,"⚠️ Attention","🔴 Critique")) -> ✅ Conforme
B15: 8 | C15: Autonomie Financière (CP / Actif) | D15: =IFERROR(SUMIF('Données Brutes'!B2:B26,"Capitaux Propres",'Données Brutes'!D2:D26)/(SUMIF('Données Brutes'!B2:B26,"Actif Non Courant",'Données Brutes'!D2:D26)+SUMIF('Données Brutes'!B2:B26,"Actif Courant",'Données Brutes'!D2:D26)),0) -> 0.51145698 | E15: =IFERROR(SUMIF('Données Brutes'!B2:B26,"Capitaux Propres",'Données Brutes'!E2:E26)/(SUMIF('Données Brutes'!B2:B26,"Actif Non Courant",'Données Brutes'!E2:E26)+SUMIF('Données Brutes'!B2:B26,"Actif Courant",'Données Brutes'!E2:E26)),0) -> 0.47873865 | F15: =IFERROR(SUMIF('Données Brutes'!B2:B26,"Capitaux Propres",'Données Brutes'!F2:F26)/(SUMIF('Données Brutes'!B2:B26,"Actif Non Courant",'Données Brutes'!F2:F26)+SUMIF('Données Brutes'!B2:B26,"Actif Courant",'Données Brutes'!F2:F26)),0) -> 0.51678376 | G15: > 33% | H15: =IFERROR((F15-E15)/ABS(E15),0) -> 0.079469476 | I15: =IF(F15>=0.4,"✅ Conforme",IF(F15>=0.33,"⚠️ Attention","🔴 Critique")) -> ✅ Conforme
B16: 9 | C16: Gearing — Endettement Net / CP | D16: =IFERROR((((SUMIF('Données Brutes'!B2:B26,"Actif Non Courant",'Données Brutes'!D2:D26)+SUMIF('Données Brutes'!B2:B26,"Actif Courant",'Données Brutes'!D2:D26))-SUMIF('Données Brutes'!B2:B26,"Capitaux Propres",'Données Brutes'!D2:D26))-(SUMIF('Données Brutes'!A2:A26,"Trésorerie active",'Données Brutes'!D2:D26)+SUMIF('Données Brutes'!A2:A26,"VMP",'Données Brutes'!D2:D26)))/SUMIF('Données Brutes'!B2:B26,"Capitaux Propres",'Données Brutes'!D2:D26),0) -> 0.84530854 | E16: =IFERROR((((SUMIF('Données Brutes'!B2:B26,"Actif Non Courant",'Données Brutes'!E2:E26)+SUMIF('Données Brutes'!B2:B26,"Actif Courant",'Données Brutes'!E2:E26))-SUMIF('Données Brutes'!B2:B26,"Capitaux Propres",'Données Brutes'!E2:E26))-(SUMIF('Données Brutes'!A2:A26,"Trésorerie active",'Données Brutes'!E2:E26)+SUMIF('Données Brutes'!A2:A26,"VMP",'Données Brutes'!E2:E26)))/SUMIF('Données Brutes'!B2:B26,"Capitaux Propres",'Données Brutes'!E2:E26),0) -> 0.98902196 | F16: =IFERROR((((SUMIF('Données Brutes'!B2:B26,"Actif Non Courant",'Données Brutes'!F2:F26)+SUMIF('Données Brutes'!B2:B26,"Actif Courant",'Données Brutes'!F2:F26))-SUMIF('Données Brutes'!B2:B26,"Capitaux Propres",'Données Brutes'!F2:F26))-(SUMIF('Données Brutes'!A2:A26,"Trésorerie active",'Données Brutes'!F2:F26)+SUMIF('Données Brutes'!A2:A26,"VMP",'Données Brutes'!F2:F26)))/SUMIF('Données Brutes'!B2:B26,"Capitaux Propres",'Données Brutes'!F2:F26),0) -> 0.78776435 | G16: < 0,5 | H16: =IFERROR((F16-E16)/ABS(E16),0) -> -0.20349154 | I16: =IF(F16<0.5,"✅ Conforme",IF(F16<1,"⚠️ Attention","🔴 Critique")) -> ⚠️ Attention
B17: 10 | C17: Capacité de Remboursement (ans) | D17: =IFERROR((((SUMIF('Données Brutes'!B2:B26,"Actif Non Courant",'Données Brutes'!D2:D26)+SUMIF('Données Brutes'!B2:B26,"Actif Courant",'Données Brutes'!D2:D26))-SUMIF('Données Brutes'!B2:B26,"Capitaux Propres",'Données Brutes'!D2:D26))-(SUMIF('Données Brutes'!A2:A26,"Trésorerie active",'Données Brutes'!D2:D26)+SUMIF('Données Brutes'!A2:A26,"VMP",'Données Brutes'!D2:D26)))/(SUMIF('Données Brutes'!A2:A26,"Résultat net",'Données Brutes'!D2:D26)+SUMIF('Données Brutes'!A38:A56,"Dotations amortissements",'Données Brutes'!D38:D56)+SUMIF('Données Brutes'!A38:A56,"Dotations provisions exploit.",'Données Brutes'!D38:D56)),0) -> 3.0721966 | E17: =IFERROR((((SUMIF('Données Brutes'!B2:B26,"Actif Non Courant",'Données Brutes'!E2:E26)+SUMIF('Données Brutes'!B2:B26,"Actif Courant",'Données Brutes'!E2:E26))-SUMIF('Données Brutes'!B2:B26,"Capitaux Propres",'Données Brutes'!E2:E26))-(SUMIF('Données Brutes'!A2:A26,"Trésorerie active",'Données Brutes'!E2:E26)+SUMIF('Données Brutes'!A2:A26,"VMP",'Données Brutes'!E2:E26)))/(SUMIF('Données Brutes'!A2:A26,"Résultat net",'Données Brutes'!E2:E26)+SUMIF('Données Brutes'!A38:A56,"Dotations amortissements",'Données Brutes'!E38:E56)+SUMIF('Données Brutes'!A38:A56,"Dotations provisions exploit.",'Données Brutes'!E38:E56)),0) -> 2.8766328 | F17: =IFERROR((((SUMIF('Données Brutes'!B2:B26,"Actif Non Courant",'Données Brutes'!F2:F26)+SUMIF('Données Brutes'!B2:B26,"Actif Courant",'Données Brutes'!F2:F26))-SUMIF('Données Brutes'!B2:B26,"Capitaux Propres",'Données Brutes'!F2:F26))-(SUMIF('Données Brutes'!A2:A26,"Trésorerie active",'Données Brutes'!F2:F26)+SUMIF('Données Brutes'!A2:A26,"VMP",'Données Brutes'!F2:F26)))/(SUMIF('Données Brutes'!A2:A26,"Résultat net",'Données Brutes'!F2:F26)+SUMIF('Données Brutes'!A38:A56,"Dotations amortissements",'Données Brutes'!F38:F56)+SUMIF('Données Brutes'!A38:A56,"Dotations provisions exploit.",'Données Brutes'!F38:F56)),0) -> 2.7556143 | G17: < 3 ans | H17: =IFERROR((F17-E17)/ABS(E17),0) -> -0.042069511 | I17: =IF(F17<2,"✅ Conforme",IF(F17<3,"⚠️ Attention","🔴 Critique")) -> ⚠️ Attention
B18: 11 | C18: Couverture des Intérêts (EBITDA / Charges Fin.) | D18: =IFERROR((SUMIF('Données Brutes'!A38:A56,"Chiffre d'affaires net",'Données Brutes'!D38:D56)+SUMIF('Données Brutes'!A38:A56,"Production stockée",'Données Brutes'!D38:D56)+SUMIF('Données Brutes'!A38:A56,"Production immobilisée",'Données Brutes'!D38:D56)+SUMIF('Données Brutes'!A38:A56,"Subventions exploitation",'Données Brutes'!D38:D56)-SUMIF('Données Brutes'!A38:A56,"Achats matières premières",'Données Brutes'!D38:D56)-SUMIF('Données Brutes'!A38:A56,"Variation stocks MP",'Données Brutes'!D38:D56)-SUMIF('Données Brutes'!A38:A56,"Autres achats & charges ext.",'Données Brutes'!D38:D56)-SUMIF('Données Brutes'!A38:A56,"Impôts & taxes",'Données Brutes'!D38:D56)-SUMIF('Données Brutes'!A38:A56,"Charges de personnel",'Données Brutes'!D38:D56))/SUMIF('Données Brutes'!A38:A56,"Charges financières",'Données Brutes'!D38:D56),0) -> 10.473684 | E18: =IFERROR((SUMIF('Données Brutes'!A38:A56,"Chiffre d'affaires net",'Données Brutes'!E38:E56)+SUMIF('Données Brutes'!A38:A56,"Production stockée",'Données Brutes'!E38:E56)+SUMIF('Données Brutes'!A38:A56,"Production immobilisée",'Données Brutes'!E38:E56)+SUMIF('Données Brutes'!A38:A56,"Subventions exploitation",'Données Brutes'!E38:E56)-SUMIF('Données Brutes'!A38:A56,"Achats matières premières",'Données Brutes'!E38:E56)-SUMIF('Données Brutes'!A38:A56,"Variation stocks MP",'Données Brutes'!E38:E56)-SUMIF('Données Brutes'!A38:A56,"Autres achats & charges ext.",'Données Brutes'!E38:E56)-SUMIF('Données Brutes'!A38:A56,"Impôts & taxes",'Données Brutes'!E38:E56)-SUMIF('Données Brutes'!A38:A56,"Charges de personnel",'Données Brutes'!E38:E56))/SUMIF('Données Brutes'!A38:A56,"Charges financières",'Données Brutes'!E38:E56),0) -> 12.426471 | F18: =IFERROR((SUMIF('Données Brutes'!A38:A56,"Chiffre d'affaires net",'Données Brutes'!F38:F56)+SUMIF('Données Brutes'!A38:A56,"Production stockée",'Données Brutes'!F38:F56)+SUMIF('Données Brutes'!A38:A56,"Production immobilisée",'Données Brutes'!F38:F56)+SUMIF('Données Brutes'!A38:A56,"Subventions exploitation",'Données Brutes'!F38:F56)-SUMIF('Données Brutes'!A38:A56,"Achats matières premières",'Données Brutes'!F38:F56)-SUMIF('Données Brutes'!A38:A56,"Variation stocks MP",'Données Brutes'!F38:F56)-SUMIF('Données Brutes'!A38:A56,"Autres achats & charges ext.",'Données Brutes'!F38:F56)-SUMIF('Données Brutes'!A38:A56,"Impôts & taxes",'Données Brutes'!F38:F56)-SUMIF('Données Brutes'!A38:A56,"Charges de personnel",'Données Brutes'!F38:F56))/SUMIF('Données Brutes'!A38:A56,"Charges financières",'Données Brutes'!F38:F56),0) -> 12.230769 | G18: > 3,0x | H18: =IFERROR((F18-E18)/ABS(E18),0) -> -0.015748748 | I18: =IF(F18>=5,"✅ Conforme",IF(F18>=3,"⚠️ Attention","🔴 Critique")) -> ✅ Conforme
B19: 12 | C19: Dettes LT / Capitaux Permanents | D19: =IFERROR(SUMIF('Données Brutes'!B2:B26,"Dettes Non Courantes",'Données Brutes'!D2:D26)/(SUMIF('Données Brutes'!B2:B26,"Capitaux Propres",'Données Brutes'!D2:D26)+SUMIF('Données Brutes'!B2:B26,"Dettes Non Courantes",'Données Brutes'!D2:D26)),0) -> 0.32050546 | E19: =IFERROR(SUMIF('Données Brutes'!B2:B26,"Dettes Non Courantes",'Données Brutes'!E2:E26)/(SUMIF('Données Brutes'!B2:B26,"Capitaux Propres",'Données Brutes'!E2:E26)+SUMIF('Données Brutes'!B2:B26,"Dettes Non Courantes",'Données Brutes'!E2:E26)),0) -> 0.32886805 | F19: =IFERROR(SUMIF('Données Brutes'!B2:B26,"Dettes Non Courantes",'Données Brutes'!F2:F26)/(SUMIF('Données Brutes'!B2:B26,"Capitaux Propres",'Données Brutes'!F2:F26)+SUMIF('Données Brutes'!B2:B26,"Dettes Non Courantes",'Données Brutes'!F2:F26)),0) -> 0.31327801 | G19: < 50% | H19: =IFERROR((F19-E19)/ABS(E19),0) -> -0.04740516 | I19: =IF(F19<0.4,"✅ Conforme",IF(F19<0.5,"⚠️ Attention","🔴 Critique")) -> ✅ Conforme
